Workbook

Sheet 매칭_작업안내
B3: 📋 생산부 재고 매칭 작업 안내
B5: ▶ 이 파일의 목적
B6: ① 생산부 품목과 창고 품목을 1:1로 매칭 | N6: 6
B7: ② 각 품목에 ERP 코드 부여 (모델기호 + 공정타입)
B8: ③ 매칭/코드 결과를 통합 마스터 데이터로 정리
B10: ━━━━━━━━━━━━━━━━━━━━━━━━━━━━━━━━━━━━━━━━━━━━━━━━━━━━━━━━━━━━━━━━
B11: 【작업 1】 창고 품명 매칭 (E열)
B12: ━━━━━━━━━━━━━━━━━━━━━━━━━━━━━━━━━━━━━━━━━━━━━━━━━━━━━━━━━━━━━━━━
B13: ▶ 작업 시트
B14: ① 튜브파트_재고현황 ② 고압진공_재고현황 ③ 조립자재_재고현황
B16: ▶ 작업 방법
B17: STEP 1. 「생산부_재고_매칭작업.xlsx」을 왼쪽 화면에 띄움
B18: STEP 2. 「창고_재고.xlsx」를 오른쪽 화면에 띄움
B19: STEP 3. 생산부 시트의 한 행씩 품목 확인 → 창고 파일에서 같은 품목 찾기
B20: STEP 4. 창고 파일의 「품목」 셀을 복사 (Ctrl+C)
... B67: 두 파일 (생산부_재고_매칭작업.xlsx + 창고_재고.xlsx) 같은 폴더에 보관

Sheet 튜브파트_재고현황
A1: 부서 | B1: 분류 | C1: 모델 | D1: 품목 | E1: ▼ 창고 품명 (창고파일에서 복사→붙여넣기) | F1: 원자재 | G1: 반제품 | H1: 완제품 | I1: 코드 | J1: 3 (DX3000) | K1: 4 (ADX4000W) | L1: 6 (ADX6000FB) | M1: 7 (COCOON) | N1: 8 (SOLO) | O1: ? (신제품) | P1: ERP 코드 {모델}-{공정} | Q1: 바로가기 (마스터로) | R1: 마스터행 | S1: 마스터시트
A2: 튜브 | B2: 공용 | D2: 전극(70kV) | E2: 전극(70kV) (순철 도금) [DXDR-070] | F2: O | I2: =IFERROR(IF(OR($F2="O",$G2="O",$H2="O"),CHOOSE(MATCH($A2,{"튜브","고압","진공","튜닝","조립","출하"},0),"T","H","V","N","A","P")&IF($F2="O","R",IF($G2="O","A",IF($H2="O","F",""))),""),"") | M2: O | P2: =IF($I2="","",IF($J2="O","3","")&IF($K2="O","4","")&IF($L2="O","6","")&IF($M2="O","7","")&IF($N2="O","8","")&IF($O2="O","?","")&IF(OR($J2="O",$K2="O",$L2="O",$M2="O",$N2="O",$O2="O"),"-","")&$I2) | Q2: =HYPERLINK("#'마스터_품목'!A2","→ 마스터 R2") | R2: 2 | S2: 마스터_품목
A3: 튜브 | B3: 공용 | D3: 텅스텐 필라멘트 | E3: 텅스텐 필라멘트 [DXDR-070] | F3: O | I3: =IFERROR(IF(OR($F3="O",$G3="O",$H3="O"),CHOOSE(MATCH($A3,{"튜브","고압","진공","튜닝","조립","출하"},0),"T","H","V","N","A","P")&IF($F3="O","R",IF($G3="O","A",IF($H3="O","F",""))),""),"") | M3: O | P3: =IF($I3="","",IF($J3="O","3","")&IF($K3="O","4","")&IF($L3="O","6","")&IF($M3="O","7","")&IF($N3="O","8","")&IF($O3="O","?","")&IF(OR($J3="O",$K3="O",$L3="O",$M3="O",$N3="O",$O3="O"),"-","")&$I3) | Q3: =HYPERLINK("#'마스터_품목'!A3","→ 마스터 R3") | R3: 3 | S3: 마스터_품목
A4: 튜브 | B4: 공용 | D4: 게터 | E4: 게터 [DXDR-070,DXDR-100] | F4: O | I4: =IFERROR(IF(OR($F4="O",$G4="O",$H4="O"),CHOOSE(MATCH($A4,{"튜브","고압","진공","튜닝","조립","출하"},0),"T","H","V","N","A","P")&IF($F4="O","R",IF($G4="O","A",IF($H4="O","F",""))),""),"") | M4: O | P4: =IF($I4="","",IF($J4="O","3","")&IF($K4="O","4","")&IF($L4="O","6","")&IF($M4="O","7","")&IF($N4="O","8","")&IF($O4="O","?","")&IF(OR($J4="O",$K4="O",$L4="O",$M4="O",$N4="O",$O4="O"),"-","")&$I4) | Q4: =HYPERLINK("#'마스터_품목'!A4","→ 마스터 R4") | R4: 4 | S4: 마스터_품목
A5: 튜브 | B5: 공용 | D5: 전극(100kV) | E5: 전극(100kV) (순철 도금) [DXDR-100] | F5: O | I5: =IFERROR(IF(OR($F5="O",$G5="O",$H5="O"),CHOOSE(MATCH($A5,{"튜브","고압","진공","튜닝","조립","출하"},0),"T","H","V","N","A","P")&IF($F5="O","R",IF($G5="O","A",IF($H5="O","F",""))),""),"") | M5: O | P5: =IF($I5="","",IF($J5="O","3","")&IF($K5="O","4","")&IF($L5="O","6","")&IF($M5="O","7","")&IF($N5="O","8","")&IF($O5="O","?","")&IF(OR($J5="O",$K5="O",$L5="O",$M5="O",$N5="O",$O5="O"),"-","")&$I5) | Q5: =HYPERLINK("#'마스터_품목'!A5","→ 마스터 R5") | R5: 5 | S5: 마스터_품목
A6: 튜브 | B6: DXDR-70 | D6: 애노드 (70kV) | E6: 에노드 [DXDR-070] | F6: O | I6: =IFERROR(IF(OR($F6="O",$G6="O",$H6="O"),CHOOSE(MATCH($A6,{"튜브","고압","진공","튜닝","조립","출하"},0),"T","H","V","N","A","P")&IF($F6="O","R",IF($G6="O","A",IF($H6="O","F",""))),""),"") | M6: O | P6: =IF($I6="","",IF($J6="O","3","")&IF($K6="O","4","")&IF($L6="O","6","")&IF($M6="O","7","")&IF($N6="O","8","")&IF($O6="O","?","")&IF(OR($J6="O",$K6="O",$L6="O",$M6="O",$N6="O",$O6="O"),"-","")&$I6) | Q6: =HYPERLINK("#'마스터_품목'!A6","→ 마스터 R6") | R6: 6 | S6: 마스터_품목
A7: 튜브 | B7: DXDR-70 | D7: 포커서 (70kV) | E7: 포커서 [DXDR-070] | F7: O | I7: =IFERROR(IF(OR($F7="O",$G7="O",$H7="O"),CHOOSE(MATCH($A7,{"튜브","고압","진공","튜닝","조립","출하"},0),"T","H","V","N","A","P")&IF($F7="O","R",IF($G7="O","A",IF($H7="O","F",""))),""),"") | M7: O | P7: =IF($I7="","",IF($J7="O","3","")&IF($K7="O","4","")&IF($L7="O","6","")&IF($M7="O","7","")&IF($N7="O","8","")&IF($O7="O","?","")&IF(OR($J7="O",$K7="O",$L7="O",$M7="O",$N7="O",$O7="O"),"-","")&$I7) | Q7: =HYPERLINK("#'마스터_품목'!A7","→ 마스터 R7") | R7: 7 | S7: 마스터_품목
A8: 튜브 | B8: DXDR-70 | D8: 세라믹 바디 (70kV) | E8: 세라믹 바디 [DXDR-070] | F8: O | I8: =IFERROR(IF(OR($F8="O",$G8="O",$H8="O"),CHOOSE(MATCH($A8,{"튜브","고압","진공","튜닝","조립","출하"},0),"T","H","V","N","A","P")&IF($F8="O","R",IF($G8="O","A",IF($H8="O","F",""))),""),"") | M8: O | P8: =IF($I8="","",IF($J8="O","3","")&IF($K8="O","4","")&IF($L8="O","6","")&IF($M8="O","7","")&IF($N8="O","8","")&IF($O8="O","?","")&IF(OR($J8="O",$K8="O",$L8="O",$M8="O",$N8="O",$O8="O"),"-","")&$I8) | Q8: =HYPERLINK("#'마스터_품목'!A8","→ 마스터 R8") | R8: 8 | S8: 마스터_품목
A9: 튜브 | B9: DXDR-70 | D9: 세라믹 스템 (70kV) | E9: 세라믹 스템 [DXDR-070] | F9: O | I9: =IFERROR(IF(OR($F9="O",$G9="O",$H9="O"),CHOOSE(MATCH($A9,{"튜브","고압","진공","튜닝","조립","출하"},0),"T","H","V","N","A","P")&IF($F9="O","R",IF($G9="O","A",IF($H9="O","F",""))),""),"") | M9: O | P9: =IF($I9="","",IF($J9="O","3","")&IF($K9="O","4","")&IF($L9="O","6","")&IF($M9="O","7","")&IF($N9="O","8","")&IF($O9="O","?","")&IF(OR($J9="O",$K9="O",$L9="O",$M9="O",$N9="O",$O9="O"),"-","")&$I9) | Q9: =HYPERLINK("#'마스터_품목'!A9","→ 마스터 R9") | R9: 9 | S9: 마스터_품목
A10: 튜브 | B10: DXDR-70 | D10: 필러 (70kV) | E10: 필러 [DXDR-070] | F10: O | I10: =IFERROR(IF(OR($F10="O",$G10="O",$H10="O"),CHOOSE(MATCH($A10,{"튜브","고압","진공","튜닝","조립","출하"},0),"T","H","V","N","A","P")&IF($F10="O","R",IF($G10="O","A",IF($H10="O","F",""))),""),"") | M10: O | P10: =IF($I10="","",IF($J10="O","3","")&IF($K10="O","4","")&IF($L10="O","6","")&IF($M10="O","7","")&IF($N10="O","8","")&IF($O10="O","?","")&IF(OR($J10="O",$K10="O",$L10="O",$M10="O",$N10="O",$O10="O"),"-","")&$I10) | Q10: =HYPERLINK("#'마스터_품목'!A10","→ 마스터 R10") | R10: 10 | S10: 마스터_품목
A11: 튜브 | B11: DXDR-70 | D11: 전극 필러 (70kV) | E11: 전극 필러 [DXDR-070] | F11: O | I11: =IFERROR(IF(OR($F11="O",$G11="O",$H11="O"),CHOOSE(MATCH($A11,{"튜브","고압","진공","튜닝","조립","출하"},0),"T","H","V","N","A","P")&IF($F11="O","R",IF($G11="O","A",IF($H11="O","F",""))),""),"") | M11: O | P11: =IF($I11="","",IF($J11="O","3","")&IF($K11="O","4","")&IF($L11="O","6","")&IF($M11="O","7","")&IF($N11="O","8","")&IF($O11="O","?","")&IF(OR($J11="O",$K11="O",$L11="O",$M11="O",$N11="O",$O11="O"),"-","")&$I11) | Q11: =HYPERLINK("#'마스터_품목'!A11","→ 마스터 R11") | R11: 11 | S11: 마스터_품목
A12: 튜브 | B12: DXDR-100 | D12: 애노드 (100kV) | E12: 에노드 [DXDR-100] | F12: O | I12: =IFERROR(IF(OR($F12="O",$G12="O",$H12="O"),CHOOSE(MATCH($A12,{"튜브","고압","진공","튜닝","조립","출하"},0),"T","H","V","N","A","P")&IF($F12="O","R",IF($G12="O","A",IF($H12="O","F",""))),""),"") | O12: O | P12: =IF($I12="","",IF($J12="O","3","")&IF($K12="O","4","")&IF($L12="O","6","")&IF($M12="O","7","")&IF($N12="O","8","")&IF($O12="O","?","")&IF(OR($J12="O",$K12="O",$L12="O",$M12="O",$N12="O",$O12="O"),"-","")&$I12) | Q12: =HYPERLINK("#'마스터_품목'!A12","→ 마스터 R12") | R12: 12 | S12: 마스터_품목
A13: 튜브 | B13: DXDR-100 | D13: 에노드 링 | E13: 에노드 링 [DXDR-100] | F13: O | I13: =IFERROR(IF(OR($F13="O",$G13="O",$H13="O"),CHOOSE(MATCH($A13,{"튜브","고압","진공","튜닝","조립","출하"},0),"T","H","V","N","A","P")&IF($F13="O","R",IF($G13="O","A",IF($H13="O","F",""))),""),"") | O13: O | P13: =IF($I13="","",IF($J13="O","3","")&IF($K13="O","4","")&IF($L13="O","6","")&IF($M13="O","7","")&IF($N13="O","8","")&IF($O13="O","?","")&IF(OR($J13="O",$K13="O",$L13="O",$M13="O",$N13="O",$O13="O"),"-","")&$I13) | Q13: =HYPERLINK("#'마스터_품목'!A13","→ 마스터 R13") | R13: 13 | S13: 마스터_품목
A14: 튜브 | B14: DXDR-100 | D14: 포커서 (100kV) | E14: 포커서 [DXDR-100] | F14: O | I14: =IFERROR(IF(OR($F14="O",$G14="O",$H14="O"),CHOOSE(MATCH($A14,{"튜브","고압","진공","튜닝","조립","출하"},0),"T","H","V","N","A","P")&IF($F14="O","R",IF($G14="O","A",IF($H14="O","F",""))),""),"") | O14: O | P14: =IF($I14="","",IF($J14="O","3","")&IF($K14="O","4","")&IF($L14="O","6","")&IF($M14="O","7","")&IF($N14="O","8","")&IF($O14="O","?","")&IF(OR($J14="O",$K14="O",$L14="O",$M14="O",$N14="O",$O14="O"),"-","")&$I14) | Q14: =HYPERLINK("#'마스터_품목'!A14","→ 마스터 R14") | R14: 14 | S14: 마스터_품목
A15: 튜브 | B15: DXDR-100 | D15: 세라믹 바디 (100kV) | E15: 세라믹 바디 [DXDR-100] | F15: O | I15: =IFERROR(IF(OR($F15="O",$G15="O",$H15="O"),CHOOSE(MATCH($A15,{"튜브","고압","진공","튜닝","조립","출하"},0),"T","H","V","N","A","P")&IF($F15="O","R",IF($G15="O","A",IF($H15="O","F",""))),""),"") | O15: O | P15: =IF($I15="","",IF($J15="O","3","")&IF($K15="O","4","")&IF($L15="O","6","")&IF($M15="O","7","")&IF($N15="O","8","")&IF($O15="O","?","")&IF(OR($J15="O",$K15="O",$L15="O",$M15="O",$N15="O",$O15="O"),"-","")&$I15) | Q15: =HYPERLINK("#'마스터_품목'!A15","→ 마스터 R15") | R15: 15 | S15: 마스터_품목
A16: 튜브 | B16: DXDR-100 | D16: 세라믹 슬리브 | E16: 세라믹 슬리브 [DXDR-100] | F16: O | I16: =IFERROR(IF(OR($F16="O",$G16="O",$H16="O"),CHOOSE(MATCH($A16,{"튜브","고압","진공","튜닝","조립","출하"},0),"T","H","V","N","A","P")&IF($F16="O","R",IF($G16="O","A",IF($H16="O","F",""))),""),"") | O16: O | P16: =IF($I16="","",IF($J16="O","3","")&IF($K16="O","4","")&IF($L16="O","6","")&IF($M16="O","7","")&IF($N16="O","8","")&IF($O16="O","?","")&IF(OR($J16="O",$K16="O",$L16="O",$M16="O",$N16="O",$O16="O"),"-","")&$I16) | Q16: =HYPERLINK("#'마스터_품목'!A16","→ 마스터 R16") | R16: 16 | S16: 마스터_품목
A17: 튜브 | B17: DXDR-100 | D17: 필러 (100kV) | E17: 필러 [DXDR-100] | F17: O | I17: =IFERROR(IF(OR($F17="O",$G17="O",$H17="O"),CHOOSE(MATCH($A17,{"튜브","고압","진공","튜닝","조립","출하"},0),"T","H","V","N","A","P")&IF($F17="O","R",IF($G17="O","A",IF($H17="O","F",""))),""),"") | O17: O | P17: =IF($I17="","",IF($J17="O","3","")&IF($K17="O","4","")&IF($L17="O","6","")&IF($M17="O","7","")&IF($N17="O","8","")&IF($O17="O","?","")&IF(OR($J17="O",$K17="O",$L17="O",$M17="O",$N17="O",$O17="O"),"-","")&$I17) | Q17: =HYPERLINK("#'마스터_품목'!A17","→ 마스터 R17") | R17: 17 | S17: 마스터_품목
A18: 튜브 | B18: DXDR-100 | D18: 전극 필러 (100kV) | E18: 전극 필러 [DXDR-100] | F18: O | I18: =IFERROR(IF(OR($F18="O",$G18="O",$H18="O"),CHOOSE(MATCH($A18,{"튜브","고압","진공","튜닝","조립","출하"},0),"T","H","V","N","A","P")&IF($F18="O","R",IF($G18="O","A",IF($H18="O","F",""))),""),"") | O18: O | P18: =IF($I18="","",IF($J18="O","3","")&IF($K18="O","4","")&IF($L18="O","6","")&IF($M18="O","7","")&IF($N18="O","8","")&IF($O18="O","?","")&IF(OR($J18="O",$K18="O",$L18="O",$M18="O",$N18="O",$O18="O"),"-","")&$I18) | Q18: =HYPERLINK("#'마스터_품목'!A18","→ 마스터 R18") | R18: 18 | S18: 마스터_품목
A19: 튜브 | B19: 완제품 튜브 | D19: DXDR-70 튜브 | H19: O | I19: =IFERROR(IF(OR($F19="O",$G19="O",$H19="O"),CHOOSE(MATCH($A19,{"튜브","고압","진공","튜닝","조립","출하"},0),"T","H","V","N","A","P")&IF($F19="O","R",IF($G19="O","A",IF($H19="O","F",""))),""),"") | M19: O | P19: =IF($I19="","",IF($J19="O","3","")&IF($K19="O","4","")&IF($L19="O","6","")&IF($M19="O","7","")&IF($N19="O","8","")&IF($O19="O","?","")&IF(OR($J19="O",$K19="O",$L19="O",$M19="O",$N19="O",$O19="O"),"-","")&$I19) | Q19: =HYPERLINK("#'마스터_품목'!A19","→ 마스터 R19") | R19: 19 | S19: 마스터_품목
A20: 튜브 | B20: 완제품 튜브 | D20: DXDR-100 튜브 | H20: O | I20: =IFERROR(IF(OR($F20="O",$G20="O",$H20="O"),CHOOSE(MATCH($A20,{"튜브","고압","진공","튜닝","조립","출하"},0),"T","H","V","N","A","P")&IF($F20="O","R",IF($G20="O","A",IF($H20="O","F",""))),""),"") | O20: O | P20: =IF($I20="","",IF($J20="O","3","")&IF($K20="O","4","")&IF($L20="O","6","")&IF($M20="O","7","")&IF($N20="O","8","")&IF($O20="O","?","")&IF(OR($J20="O",$K20="O",$L20="O",$M20="O",$N20="O",$O20="O"),"-","")&$I20) | Q20: =HYPERLINK("#'마스터_품목'!A20","→ 마스터 R20") | R20: 20 | S20: 마스터_품목

Sheet 고압진공_재고현황
A1: 부서 | B1: 분류 | C1: 모델 | D1: 품목 | E1: ▼ 창고 품명 (창고파일에서 복사→붙여넣기) | F1: 원자재 | G1: 반제품 | H1: 완제품 | I1: 코드 | J1: 3 (DX3000) | K1: 4 (ADX4000W) | L1: 6 (ADX6000FB) | M1: 7 (COCOON) | N1: 8 (SOLO) | O1: ? (신제품) | P1: ERP 코드 {모델}-{공정} | Q1: 바로가기 (마스터로) | R1: 마스터행 | S1: 마스터시트
A2: 고압 | B2: 튜브 | C2: DX3000, ADX4000W | D2: 캐논튜브 [ D-081B ] _ 60KV | E2: TUBE (60KV D-081B) [DX3000, ADX4000W] | F2: O | I2: =IFERROR(IF(OR($F2="O",$G2="O",$H2="O"),CHOOSE(MATCH($A2,{"튜브","고압","진공","튜닝","조립","출하"},0),"T","H","V","N","A","P")&IF($F2="O","R",IF($G2="O","A",IF($H2="O","F",""))),""),"") | J2: O | K2: O | P2: =IF($I2="","",IF($J2="O","3","")&IF($K2="O","4","")&IF($L2="O","6","")&IF($M2="O","7","")&IF($N2="O","8","")&IF($O2="O","?","")&IF(OR($J2="O",$K2="O",$L2="O",$M2="O",$N2="O",$O2="O"),"-","")&$I2) | Q2: =HYPERLINK("#'마스터_품목'!A21","→ 마스터 R21") | R2: 21 | S2: 마스터_품목
A3: 고압 | B3: 튜브 | C3: COCOON, SOLO | D3: 캐논튜브 [ D-041 ] _ 70KV | E3: TUBE (70KV D-041) [COCOON] | F3: O | I3: =IFERROR(IF(OR($F3="O",$G3="O",$H3="O"),CHOOSE(MATCH($A3,{"튜브","고압","진공","튜닝","조립","출하"},0),"T","H","V","N","A","P")&IF($F3="O","R",IF($G3="O","A",IF($H3="O","F",""))),""),"") | M3: O | N3: O | P3: =IF($I3="","",IF($J3="O","3","")&IF($K3="O","4","")&IF($L3="O","6","")&IF($M3="O","7","")&IF($N3="O","8","")&IF($O3="O","?","")&IF(OR($J3="O",$K3="O",$L3="O",$M3="O",$N3="O",$O3="O"),"-","")&$I3) | Q3: =HYPERLINK("#'마스터_품목'!A22","→ 마스터 R22") | R3: 22 | S3: 마스터_품목
A4: 고압 | B4: 튜브 | C4: ADX6000 | D4: 캐논튜브 [ D-0813 ] _ 80KV | E4: TUBE (80KV D-0813) [ADX6000] | F4: O | I4: =IFERROR(IF(OR($F4="O",$G4="O",$H4="O"),CHOOSE(MATCH($A4,{"튜브","고압","진공","튜닝","조립","출하"},0),"T","H","V","N","A","P")&IF($F4="O","R",IF($G4="O","A",IF($H4="O","F",""))),""),"") | L4: O | P4: =IF($I4="","",IF($J4="O","3","")&IF($K4="O","4","")&IF($L4="O","6","")&IF($M4="O","7","")&IF($N4="O","8","")&IF($O4="O","?","")&IF(OR($J4="O",$K4="O",$L4="O",$M4="O",$N4="O",$O4="O"),"-","")&$I4) | Q4: =HYPERLINK("#'마스터_품목'!A23","→ 마스터 R23") | R4: 23 | S4: 마스터_품목
A5: 고압 | B5: 튜브 | C5: DX3000, ADX4000W, ADX6000, SOLO | D5: 세라믹튜브 [DXDR-070] _ 70KV | E5: TUBE (70KV DXDR-070) [SOLO] | F5: O | I5: =IFERROR(IF(OR($F5="O",$G5="O",$H5="O"),CHOOSE(MATCH($A5,{"튜브","고압","진공","튜닝","조립","출하"},0),"T","H","V","N","A","P")&IF($F5="O","R",IF($G5="O","A",IF($H5="O","F",""))),""),"") | J5: O | K5: O | L5: O | N5: O | P5: =IF($I5="","",IF($J5="O","3","")&IF($K5="O","4","")&IF($L5="O","6","")&IF($M5="O","7","")&IF($N5="O","8","")&IF($O5="O","?","")&IF(OR($J5="O",$K5="O",$L5="O",$M5="O",$N5="O",$O5="O"),"-","")&$I5) | Q5: =HYPERLINK("#'마스터_품목'!A24","→ 마스터 R24") | R5: 24 | S5: 마스터_품목
A6: 고압 | B6: 튜브 | C6: ADX6000 | D6: 세라믹튜브 [DXDR-100] _ 100KV | E6: TUBE (100Kv DXDR-100) [100kV] | F6: O | I6: =IFERROR(IF(OR($F6="O",$G6="O",$H6="O"),CHOOSE(MATCH($A6,{"튜브","고압","진공","튜닝","조립","출하"},0),"T","H","V","N","A","P")&IF($F6="O","R",IF($G6="O","A",IF($H6="O","F",""))),""),"") | L6: O | P6: =IF($I6="","",IF($J6="O","3","")&IF($K6="O","4","")&IF($L6="O","6","")&IF($M6="O","7","")&IF($N6="O","8","")&IF($O6="O","?","")&IF(OR($J6="O",$K6="O",$L6="O",$M6="O",$N6="O",$O6="O"),"-","")&$I6) | Q6: =HYPERLINK("#'마스터_품목'!A25","→ 마스터 R25") | R6: 25 | S6: 마스터_품목
A7: 고압 | B7: 튜브 | C7: ADX6000 | D7: CEI튜브 [OX-70] _ 90KV | E7: TUBE (90kV OX / 70-1.0) [ADX6000] | F7: O | I7: =IFERROR(IF(OR($F7="O",$G7="O",$H7="O"),CHOOSE(MATCH($A7,{"튜브","고압","진공","튜닝","조립","출하"},0),"T","H","V","N","A","P")&IF($F7="O","R",IF($G7="O","A",IF($H7="O","F",""))),""),"") | L7: O | P7: =IF($I7="","",IF($J7="O","3","")&IF($K7="O","4","")&IF($L7="O","6","")&IF($M7="O","7","")&IF($N7="O","8","")&IF($O7="O","?","")&IF(OR($J7="O",$K7="O",$L7="O",$M7="O",$N7="O",$O7="O"),"-","")&$I7) | Q7: =HYPERLINK("#'마스터_품목'!A26","→ 마스터 R26") | R7: 26 | S7: 마스터_품목
A8: 고압 | B8: 부품 | C8: DX3000, ADX4000W | D8: 고압다이오드 2CL77 [20KV, 5mA] | E8: 고압 다이오드 (2CL77 (20KV, 5mA)) [DX3000, ADX4000W] | F8: O | I8: =IFERROR(IF(OR($F8="O",$G8="O",$H8="O"),CHOOSE(MATCH($A8,{"튜브","고압","진공","튜닝","조립","출하"},0),"T","H","V","N","A","P")&IF($F8="O","R",IF($G8="O","A",IF($H8="O","F",""))),""),"") | J8: O | K8: O | P8: =IF($I8="","",IF($J8="O","3","")&IF($K8="O","4","")&IF($L8="O","6","")&IF($M8="O","7","")&IF($N8="O","8","")&IF($O8="O","?","")&IF(OR($J8="O",$K8="O",$L8="O",$M8="O",$N8="O",$O8="O"),"-","")&$I8) | Q8: =HYPERLINK("#'마스터_품목'!A27","→ 마스터 R27") | R8: 27 | S8: 마스터_품목
A9: 고압 | B9: 부품 | C9: DX3000, ADX4000W, COCOON | D9: 네온램프(NEON-5T) | E9: 네온램프 (NEON-5T.5*13 red) [DX3000, ADX4000W COCOON] | F9: O | I9: =IFERROR(IF(OR($F9="O",$G9="O",$H9="O"),CHOOSE(MATCH($A9,{"튜브","고압","진공","튜닝","조립","출하"},0),"T","H","V","N","A","P")&IF($F9="O","R",IF($G9="O","A",IF($H9="O","F",""))),""),"") | J9: O | K9: O | M9: O | P9: =IF($I9="","",IF($J9="O","3","")&IF($K9="O","4","")&IF($L9="O","6","")&IF($M9="O","7","")&IF($N9="O","8","")&IF($O9="O","?","")&IF(OR($J9="O",$K9="O",$L9="O",$M9="O",$N9="O",$O9="O"),"-","")&$I9) | Q9: =HYPERLINK("#'마스터_품목'!A28","→ 마스터 R28") | R9: 28 | S9: 마스터_품목
A10: 고압 | B10: 부품 | C10: DX3000, ADX4000W, ADX6000 | D10: RK92-11XD307J (시멘트 저항) | E10: 1.7W,10kV 시멘트저항 짧은 것 (RK92-11XD 307J (1.7W,10kV,±5%,300ppm,Flat)) [DX3000, ADX4000W] | F10: O | I10: =IFERROR(IF(OR($F10="O",$G10="O",$H10="O"),CHOOSE(MATCH($A10,{"튜브","고압","진공","튜닝","조립","출하"},0),"T","H","V","N","A","P")&IF($F10="O","R",IF($G10="O","A",IF($H10="O","F",""))),""),"") | J10: O | K10: O | L10: O | P10: =IF($I10="","",IF($J10="O","3","")&IF($K10="O","4","")&IF($L10="O","6","")&IF($M10="O","7","")&IF($N10="O","8","")&IF($O10="O","?","")&IF(OR($J10="O",$K10="O",$L10="O",$M10="O",$N10="O",$O10="O"),"-","")&$I10) | Q10: =HYPERLINK("#'마스터_품목'!A29","→ 마스터 R29") | R10: 29 | S10: 마스터_품목
A11: 고압 | B11: 부품 | C11: DX3000, ADX4000W | D11: 고압용 (30㏀) | E11: 30㏀ 고압용 저항 (30㏀±1％, DIP-1/4W) [DX3000, ADX4000W ADX6000] | F11: O | I11: =IFERROR(IF(OR($F11="O",$G11="O",$H11="O"),CHOOSE(MATCH($A11,{"튜브","고압","진공","튜닝","조립","출하"},0),"T","H","V","N","A","P")&IF($F11="O","R",IF($G11="O","A",IF($H11="O","F",""))),""),"") | J11: O | K11: O | P11: =IF($I11="","",IF($J11="O","3","")&IF($K11="O","4","")&IF($L11="O","6","")&IF($M11="O","7","")&IF($N11="O","8","")&IF($O11="O","?","")&IF(OR($J11="O",$K11="O",$L11="O",$M11="O",$N11="O",$O11="O"),"-","")&$I11) | Q11: =HYPERLINK("#'마스터_품목'!A30","→ 마스터 R30") | R11: 30 | S11: 마스터_품목
A12: 고압 | B12: 부품 | C12: DX3000, ADX4000W, ADX6000 | D12: 고압용 (15㏀±1％, DIP) - 1/4W | E12: 15㏀ 고압용 저항 (15㏀±1％, DIP-1/4W) [DX3000, ADX4000W] | F12: O | I12: =IFERROR(IF(OR($F12="O",$G12="O",$H12="O"),CHOOSE(MATCH($A12,{"튜브","고압","진공","튜닝","조립","출하"},0),"T","H","V","N","A","P")&IF($F12="O","R",IF($G12="O","A",IF($H12="O","F",""))),""),"") | J12: O | K12: O | L12: O | P12: =IF($I12="","",IF($J12="O","3","")&IF($K12="O","4","")&IF($L12="O","6","")&IF($M12="O","7","")&IF($N12="O","8","")&IF($O12="O","?","")&IF(OR($J12="O",$K12="O",$L12="O",$M12="O",$N12="O",$O12="O"),"-","")&$I12) | Q12: =HYPERLINK("#'마스터_품목'!A31","→ 마스터 R31") | R12: 31 | S12: 마스터_품목
A13: 고압 | B13: 부품 | C13: ADX6000 | D13: 고압용 (500Ω±1％, DIP) - 1/4W | E13: 500Ω 고압용 저항 (500Ω±1％, DIP-1/4W) [ADX6000] | F13: O | I13: =IFERROR(IF(OR($F13="O",$G13="O",$H13="O"),CHOOSE(MATCH($A13,{"튜브","고압","진공","튜닝","조립","출하"},0),"T","H","V","N","A","P")&IF($F13="O","R",IF($G13="O","A",IF($H13="O","F",""))),""),"") | L13: O | P13: =IF($I13="","",IF($J13="O","3","")&IF($K13="O","4","")&IF($L13="O","6","")&IF($M13="O","7","")&IF($N13="O","8","")&IF($O13="O","?","")&IF(OR($J13="O",$K13="O",$L13="O",$M13="O",$N13="O",$O13="O"),"-","")&$I13) | Q13: =HYPERLINK("#'마스터_품목'!A32","→ 마스터 R32") | R13: 32 | S13: 마스터_품목
A14: 고압 | B14: 부품 | C14: DX3000, ADX4000W, ADX6000 | D14: 고압용(세라믹103) | E14: 103Z 고압용 세라믹 콘덴서 (50V F103Z) [DX3000, ADX4000W ADX6000] | F14: O | I14: =IFERROR(IF(OR($F14="O",$G14="O",$H14="O"),CHOOSE(MATCH($A14,{"튜브","고압","진공","튜닝","조립","출하"},0),"T","H","V","N","A","P")&IF($F14="O","R",IF($G14="O","A",IF($H14="O","F",""))),""),"") | J14: O | K14: O | L14: O | P14: =IF($I14="","",IF($J14="O","3","")&IF($K14="O","4","")&IF($L14="O","6","")&IF($M14="O","7","")&IF($N14="O","8","")&IF($O14="O","?","")&IF(OR($J14="O",$K14="O",$L14="O",$M14="O",$N14="O",$O14="O"),"-","")&$I14) | Q14: =HYPERLINK("#'마스터_품목'!A33","→ 마스터 R33") | R14: 33 | S14: 마스터_품목
A15: 고압 | B15: 부품 | C15: DX3000, ADX4000W | D15: DHR4E4C102K2FB 큰 콘덴서 | E15: 세라믹 큰 콘덴서 (DHR4E4C102K2FB) [DX3000, ADX4000W] | F15: O | I15: =IFERROR(IF(OR($F15="O",$G15="O",$H15="O"),CHOOSE(MATCH($A15,{"튜브","고압","진공","튜닝","조립","출하"},0),"T","H","V","N","A","P")&IF($F15="O","R",IF($G15="O","A",IF($H15="O","F",""))),""),"") | J15: O | K15: O | P15: =IF($I15="","",IF($J15="O","3","")&IF($K15="O","4","")&IF($L15="O","6","")&IF($M15="O","7","")&IF($N15="O","8","")&IF($O15="O","?","")&IF(OR($J15="O",$K15="O",$L15="O",$M15="O",$N15="O",$O15="O"),"-","")&$I15) | Q15: =HYPERLINK("#'마스터_품목'!A34","→ 마스터 R34") | R15: 34 | S15: 마스터_품목
A16: 고압 | B16: 부품 | C16: DX3000, ADX4000W, ADX6000 | D16: 3216 B 100nF | E16: 100nF 칩세라믹 콘덴서 (3216B 100nF) [DX3000, ADX4000W ADX6000] | F16: O | I16: =IFERROR(IF(OR($F16="O",$G16="O",$H16="O"),CHOOSE(MATCH($A16,{"튜브","고압","진공","튜닝","조립","출하"},0),"T","H","V","N","A","P")&IF($F16="O","R",IF($G16="O","A",IF($H16="O","F",""))),""),"") | J16: O | K16: O | L16: O | P16: =IF($I16="","",IF($J16="O","3","")&IF($K16="O","4","")&IF($L16="O","6","")&IF($M16="O","7","")&IF($N16="O","8","")&IF($O16="O","?","")&IF(OR($J16="O",$K16="O",$L16="O",$M16="O",$N16="O",$O16="O"),"-","")&$I16) | Q16: =HYPERLINK("#'마스터_품목'!A35","→ 마스터 R35") | R16: 35 | S16: 마스터_품목
A17: 고압 | B17: 부품 | C17: DX3000, ADX4000W, ADX6000, COCOON | D17: DL1500(다이오드) | E17: 고압 다이오드 (DL1500) [DX3000, ADX4000W ADX6000] | F17: O | I17: =IFERROR(IF(OR($F17="O",$G17="O",$H17="O"),CHOOSE(MATCH($A17,{"튜브","고압","진공","튜닝","조립","출하"},0),"T","H","V","N","A","P")&IF($F17="O","R",IF($G17="O","A",IF($H17="O","F",""))),""),"") | J17: O | K17: O | L17: O | P17: =IF($I17="","",IF($J17="O","3","")&IF($K17="O","4","")&IF($L17="O","6","")&IF($M17="O","7","")&IF($N17="O","8","")&IF($O17="O","?","")&IF(OR($J17="O",$K17="O",$L17="O",$M17="O",$N17="O",$O17="O"),"-","")&$I17) | Q17: =HYPERLINK("#'마스터_품목'!A36","→ 마스터 R36") | R17: 36 | S17: 마스터_품목
A18: 고압 | B18: 부품 | C18: DX3000, ADX4000W, ADX6000, COCOON | D18: HPC-2C 47k/Surge | E18: 47k Surge 저항 (HPC-2C 47k/Surge) [DX3000, ADX4000W ADX6000] | F18: O | I18: =IFERROR(IF(OR($F18="O",$G18="O",$H18="O"),CHOOSE(MATCH($A18,{"튜브","고압","진공","튜닝","조립","출하"},0),"T","H","V","N","A","P")&IF($F18="O","R",IF($G18="O","A",IF($H18="O","F",""))),""),"") | J18: O | K18: O | L18: O | M18: O | P18: =IF($I18="","",IF($J18="O","3","")&IF($K18="O","4","")&IF($L18="O","6","")&IF($M18="O","7","")&IF($N18="O","8","")&IF($O18="O","?","")&IF(OR($J18="O",$K18="O",$L18="O",$M18="O",$N18="O",$O18="O"),"-","")&$I18) | Q18: =HYPERLINK("#'마스터_품목'!A37","→ 마스터 R37") | R18: 37 | S18: 마스터_품목
A19: 고압 | B19: 부품 | C19: COCOON | D19: RK92-18XD 307J 시멘트저항 긴 것 | E19: 2.7W,15kV 시멘트저항 긴 것 (RK92-18XD 307J (2.7W,15kV,±5%,300ppm,Flat)) [COCOON] | F19: O | I19: =IFERROR(IF(OR($F19="O",$G19="O",$H19="O"),CHOOSE(MATCH($A19,{"튜브","고압","진공","튜닝","조립","출하"},0),"T","H","V","N","A","P")&IF($F19="O","R",IF($G19="O","A",IF($H19="O","F",""))),""),"") | M19: O | P19: =IF($I19="","",IF($J19="O","3","")&IF($K19="O","4","")&IF($L19="O","6","")&IF($M19="O","7","")&IF($N19="O","8","")&IF($O19="O","?","")&IF(OR($J19="O",$K19="O",$L19="O",$M19="O",$N19="O",$O19="O"),"-","")&$I19) | Q19: =HYPERLINK("#'마스터_품목'!A38","→ 마스터 R38") | R19: 38 | S19: 마스터_품목
A20: 고압 | B20: 부품 | C20: ADX6000, COCOON | D20: 680pF DHR4E4C681K2BB 무라타 작은 콘덴서 | E20: 세라믹 작은 콘덴서 Murata (680pF DHR4E4C681K2BB) [COCOON, ADX6000] | F20: O | I20: =IFERROR(IF(OR($F20="O",$G20="O",$H20="O"),CHOOSE(MATCH($A20,{"튜브","고압","진공","튜닝","조립","출하"},0),"T","H","V","N","A","P")&IF($F20="O","R",IF($G20="O","A",IF($H20="O","F",""))),""),"") | L20: O | M20: O | P20: =IF($I20="","",IF($J20="O","3","")&IF($K20="O","4","")&IF($L20="O","6","")&IF($M20="O","7","")&IF($N20="O","8","")&IF($O20="O","?","")&IF(OR($J20="O",$K20="O",$L20="O",$M20="O",$N20="O",$O20="O"),"-","")&$I20) | Q20: =HYPERLINK("#'마스터_품목'!A39","→ 마스터 R39") | R20: 39 | S20: 마스터_품목
A21: 고압 | B21: 부품 | C21: COCOON | D21: LNTK103FW 온도센서 | E21: 온도센서 (LNTK103FW) [COCOON] | F21: O | I21: =IFERROR(IF(OR($F21="O",$G21="O",$H21="O"),CHOOSE(MATCH($A21,{"튜브","고압","진공","튜닝","조립","출하"},0),"T","H","V","N","A","P")&IF($F21="O","R",IF($G21="O","A",IF($H21="O","F",""))),""),"") | M21: O | P21: =IF($I21="","",IF($J21="O","3","")&IF($K21="O","4","")&IF($L21="O","6","")&IF($M21="O","7","")&IF($N21="O","8","")&IF($O21="O","?","")&IF(OR($J21="O",$K21="O",$L21="O",$M21="O",$N21="O",$O21="O"),"-","")&$I21) | Q21: =HYPERLINK("#'마스터_품목'!A40","→ 마스터 R40") | R21: 40 | S21: 마스터_품목
A22: 고압 | B22: 부품 | C22: ADX6000 | D22: 15k/Surge | F22: O | I22: =IFERROR(IF(OR($F22="O",$G22="O",$H22="O"),CHOOSE(MATCH($A22,{"튜브","고압","진공","튜닝","조립","출하"},0),"T","H","V","N","A","P")&IF($F22="O","R",IF($G22="O","A",IF($H22="O","F",""))),""),"") | L22: O | P22: =IF($I22="","",IF($J22="O","3","")&IF($K22="O","4","")&IF($L22="O","6","")&IF($M22="O","7","")&IF($N22="O","8","")&IF($O22="O","?","")&IF(OR($J22="O",$K22="O",$L22="O",$M22="O",$N22="O",$O22="O"),"-","")&$I22) | Q22: =HYPERLINK("#'마스터_품목'!A41","→ 마스터 R41") | R22: 41 | S22: 마스터_품목
A23: 고압 | B23: 부품 | C23: COCOON | D23: DD1800 (신규 다이오드) | E23: 고압 다이오드 (DD1800) [COCOON] | F23: O | I23: =IFERROR(IF(OR($F23="O",$G23="O",$H23="O"),CHOOSE(MATCH($A23,{"튜브","고압","진공","튜닝","조립","출하"},0),"T","H","V","N","A","P")&IF($F23="O","R",IF($G23="O","A",IF($H23="O","F",""))),""),"") | M23: O | P23: =IF($I23="","",IF($J23="O","3","")&IF($K23="O","4","")&IF($L23="O","6","")&IF($M23="O","7","")&IF($N23="O","8","")&IF($O23="O","?","")&IF(OR($J23="O",$K23="O",$L23="O",$M23="O",$N23="O",$O23="O"),"-","")&$I23) | Q23: =HYPERLINK("#'마스터_품목'!A42","→ 마스터 R42") | R23: 42 | S23: 마스터_품목
A24: 진공 | B24: 부품 | C24: ADX6000 | D24: 2T 알루미늄 필터 | E24: 알루미늄 필터 (2T * Φ24) [ADX6000] | F24: O | I24: =IFERROR(IF(OR($F24="O",$G24="O",$H24="O"),CHOOSE(MATCH($A24,{"튜브","고압","진공","튜닝","조립","출하"},0),"T","H","V","N","A","P")&IF($F24="O","R",IF($G24="O","A",IF($H24="O","F",""))),""),"") | L24: O | O24: O | P24: =IF($I24="","",IF($J24="O","3","")&IF($K24="O","4","")&IF($L24="O","6","")&IF($M24="O","7","")&IF($N24="O","8","")&IF($O24="O","?","")&IF(OR($J24="O",$K24="O",$L24="O",$M24="O",$N24="O",$O24="O"),"-","")&$I24) | Q24: =HYPERLINK("#'마스터_품목'!A91","→ 마스터 R91") | R24: 91 | S24: 마스터_품목
A25: 진공 | B25: 부품 | C25: COCOON | D25: 1.2T 알루미늄 필터 | E25: 알루미늄 필터 (1.2T * Φ24) [COCOON] | F25: O | I25: =IFERROR(IF(OR($F25="O",$G25="O",$H25="O"),CHOOSE(MATCH($A25,{"튜브","고압","진공","튜닝","조립","출하"},0),"T","H","V","N","A","P")&IF($F25="O","R",IF($G25="O","A",IF($H25="O","F",""))),""),"") | J25: O | M25: O | P25: =IF($I25="","",IF($J25="O","3","")&IF($K25="O","4","")&IF($L25="O","6","")&IF($M25="O","7","")&IF($N25="O","8","")&IF($O25="O","?","")&IF(OR($J25="O",$K25="O",$L25="O",$M25="O",$N25="O",$O25="O"),"-","")&$I25) | Q25: =HYPERLINK("#'마스터_품목'!A92","→ 마스터 R92") | R25: 92 | S25: 마스터_품목
A26: 진공 | B26: 부품 | C26: DX3000, ADX4000W, ADX6000, COCOON | D26: 0.8T 알루미늄 필터 | E26: 알루미늄 필터 (0.8T * Φ24) [DX3000, ADX4000W ADX6000] | F26: O | I26: =IFERROR(IF(OR($F26="O",$G26="O",$H26="O"),CHOOSE(MATCH($A26,{"튜브","고압","진공","튜닝","조립","출하"},0),"T","H","V","N","A","P")&IF($F26="O","R",IF($G26="O","A",IF($H26="O","F",""))),""),"") | J26: O | K26: O | M26: O | N26: O | P26: =IF($I26="","",IF($J26="O","3","")&IF($K26="O","4","")&IF($L26="O","6","")&IF($M26="O","7","")&IF($N26="O","8","")&IF($O26="O","?","")&IF(OR($J26="O",$K26="O",$L26="O",$M26="O",$N26="O",$O26="O"),"-","")&$I26) | Q26: =HYPERLINK("#'마스터_품목'!A93","→ 마스터 R93") | R26: 93 | S26: 마스터_품목
A27: 진공 | B27: 부품 | C27: DX3000, ADX4000W, ADX6000, COCOON | D27: 오링 (2*18) | E27: 방사구 오링 (2*18) [공용] | F27: O | I27: =IFERROR(IF(OR($F27="O",$G27="O",$H27="O"),CHOOSE(MATCH($A27,{"튜브","고압","진공","튜닝","조립","출하"},0),"T","H","V","N","A","P")&IF($F27="O","R",IF($G27="O","A",IF($H27="O","F",""))),""),"") | J27: O | K27: O | L27: O | M27: O | N27: O | O27: O | P27: =IF($I27="","",IF($J27="O","3","")&IF($K27="O","4","")&IF($L27="O","6","")&IF($M27="O","7","")&IF($N27="O","8","")&IF($O27="O","?","")&IF(OR($J27="O",$K27="O",$L27="O",$M27="O",$N27="O",$O27="O"),"-","")&$I27) | Q27: =HYPERLINK("#'마스터_품목'!A94","→ 마스터 R94") | R27: 94 | S27: 마스터_품목
A28: 고압 | B28: 히터 트랜스 | C28: DX3000, ADX4000W, ADX6000 | D28: TIW (외경)0.7mm(내경)0.5 5000m(히터트랜스용 선) | E28: TIW 권선 (히터트랜스용 선) ((외경)0.7mm (내경)0.5mm, 4000m) [DX3000, ADX4000W ADX6000] | F28: O | I28: =IFERROR(IF(OR($F28="O",$G28="O",$H28="O"),CHOOSE(MATCH($A28,{"튜브","고압","진공","튜닝","조립","출하"},0),"T","H","V","N","A","P")&IF($F28="O","R",IF($G28="O","A",IF($H28="O","F",""))),""),"") | J28: O | K28: O | L28: O | P28: =IF($I28="","",IF($J28="O","3","")&IF($K28="O","4","")&IF($L28="O","6","")&IF($M28="O","7","")&IF($N28="O","8","")&IF($O28="O","?","")&IF(OR($J28="O",$K28="O",$L28="O",$M28="O",$N28="O",$O28="O"),"-","")&$I28) | Q28: =HYPERLINK("#'마스터_품목'!A43","→ 마스터 R43") | R28: 43 | S28: 마스터_품목
A29: 고압 | B29: 히터 트랜스 | C29: DX3000, ADX4000W, ADX6000 | D29: 40KVDC 22AWG (히터트랜스용 붉은 고압선) | E29: 히터트랜스용 고압선(적색) (40KVDC 22AWG) [DX3000, ADX4000W ADX6000] | F29: O | I29: =IFERROR(IF(OR($F29="O",$G29="O",$H29="O"),CHOOSE(MATCH($A29,{"튜브","고압","진공","튜닝","조립","출하"},0),"T","H","V","N","A","P")&IF($F29="O","R",IF($G29="O","A",IF($H29="O","F",""))),""),"") | J29: O | K29: O | L29: O | P29: =IF($I29="","",IF($J29="O","3","")&IF($K29="O","4","")&IF($L29="O","6","")&IF($M29="O","7","")&IF($N29="O","8","")&IF($O29="O","?","")&IF(OR($J29="O",$K29="O",$L29="O",$M29="O",$N29="O",$O29="O"),"-","")&$I29) | Q29: =HYPERLINK("#'마스터_품목'!A44","→ 마스터 R44") | R29: 44 | S29: 마스터_품목
A30: 고압 | B30: 히터 트랜스 | C30: ADX6000 | D30: 센더스트 코어 CS234060 | E30: 센더스트 코어 (CS234060) [ADX6000] | F30: O | I30: =IFERROR(IF(OR($F30="O",$G30="O",$H30="O"),CHOOSE(MATCH($A30,{"튜브","고압","진공","튜닝","조립","출하"},0),"T","H","V","N","A","P")&IF($F30="O","R",IF($G30="O","A",IF($H30="O","F",""))),""),"") | L30: O | P30: =IF($I30="","",IF($J30="O","3","")&IF($K30="O","4","")&IF($L30="O","6","")&IF($M30="O","7","")&IF($N30="O","8","")&IF($O30="O","?","")&IF(OR($J30="O",$K30="O",$L30="O",$M30="O",$N30="O",$O30="O"),"-","")&$I30) | Q30: =HYPERLINK("#'마스터_품목'!A45","→ 마스터 R45") | R30: 45 | S30: 마스터_품목
A31: 고압 | B31: 히터 트랜스 | C31: DX3000, ADX4000W | D31: T 코어 (히터트랜스용) | E31: T 코어 (히터트랜스용) (T31 X 8 X 19E) [DX3000, ADX4000W ADX6000] | F31: O | I31: =IFERROR(IF(OR($F31="O",$G31="O",$H31="O"),CHOOSE(MATCH($A31,{"튜브","고압","진공","튜닝","조립","출하"},0),"T","H","V","N","A","P")&IF($F31="O","R",IF($G31="O","A",IF($H31="O","F",""))),""),"") | J31: O | K31: O | P31: =IF($I31="","",IF($J31="O","3","")&IF($K31="O","4","")&IF($L31="O","6","")&IF($M31="O","7","")&IF($N31="O","8","")&IF($O31="O","?","")&IF(OR($J31="O",$K31="O",$L31="O",$M31="O",$N31="O",$O31="O"),"-","")&$I31) | Q31: =HYPERLINK("#'마스터_품목'!A46","→ 마스터 R46") | R31: 46 | S31: 마스터_품목
A32: 고압 | B32: 히터 트랜스 | C32: SOLO | D32: T 코어 (히터트랜스용) | E32: T 코어 (히터트랜스용) (TR22-14-6.5) [SOLO] | F32: O | I32: =IFERROR(IF(OR($F32="O",$G32="O",$H32="O"),CHOOSE(MATCH($A32,{"튜브","고압","진공","튜닝","조립","출하"},0),"T","H","V","N","A","P")&IF($F32="O","R",IF($G32="O","A",IF($H32="O","F",""))),""),"") | N32: O | P32: =IF($I32="","",IF($J32="O","3","")&IF($K32="O","4","")&IF($L32="O","6","")&IF($M32="O","7","")&IF($N32="O","8","")&IF($O32="O","?","")&IF(OR($J32="O",$K32="O",$L32="O",$M32="O",$N32="O",$O32="O"),"-","")&$I32) | Q32: =HYPERLINK("#'마스터_품목'!A47","→ 마스터 R47") | R32: 47 | S32: 마스터_품목
A33: 고압 | B33: 히터 트랜스 | C33: DX3000, ADX4000W | D33: 히터트랜스포머 24턴 | G33: O | I33: =IFERROR(IF(OR($F33="O",$G33="O",$H33="O"),CHOOSE(MATCH($A33,{"튜브","고압","진공","튜닝","조립","출하"},0),"T","H","V","N","A","P")&IF($F33="O","R",IF($G33="O","A",IF($H33="O","F",""))),""),"") | J33: O | K33: O | P33: =IF($I33="","",IF($J33="O","3","")&IF($K33="O","4","")&IF($L33="O","6","")&IF($M33="O","7","")&IF($N33="O","8","")&IF($O33="O","?","")&IF(OR($J33="O",$K33="O",$L33="O",$M33="O",$N33="O",$O33="O"),"-","")&$I33) | Q33: =HYPERLINK("#'마스터_품목'!A48","→ 마스터 R48") | R33: 48 | S33: 마스터_품목
A34: 고압 | B34: 히터 트랜스 | C34: ADX6000 | D34: 히터트랜스포머 20턴 작업完 | G34: O | I34: =IFERROR(IF(OR($F34="O",$G34="O",$H34="O"),CHOOSE(MATCH($A34,{"튜브","고압","진공","튜닝","조립","출하"},0),"T","H","V","N","A","P")&IF($F34="O","R",IF($G34="O","A",IF($H34="O","F",""))),""),"") | L34: O | P34: =IF($I34="","",IF($J34="O","3","")&IF($K34="O","4","")&IF($L34="O","6","")&IF($M34="O","7","")&IF($N34="O","8","")&IF($O34="O","?","")&IF(OR($J34="O",$K34="O",$L34="O",$M34="O",$N34="O",$O34="O"),"-","")&$I34) | Q34: =HYPERLINK("#'마스터_품목'!A49","→ 마스터 R49") | R34: 49 | S34: 마스터_품목
A35: 고압 | B35: 히터 트랜스 | C35: SOLO | D35: 히터트랜스포머 20턴 | G35: O | I35: =IFERROR(IF(OR($F35="O",$G35="O",$H35="O"),CHOOSE(MATCH($A35,{"튜브","고압","진공","튜닝","조립","출하"},0),"T","H","V","N","A","P")&IF($F35="O","R",IF($G35="O","A",IF($H35="O","F",""))),""),"") | N35: O | P35: =IF($I35="","",IF($J35="O","3","")&IF($K35="O","4","")&IF($L35="O","6","")&IF($M35="O","7","")&IF($N35="O","8","")&IF($O35="O","?","")&IF(OR($J35="O",$K35="O",$L35="O",$M35="O",$N35="O",$O35="O"),"-","")&$I35) | Q35: =HYPERLINK("#'마스터_품목'!A50","→ 마스터 R50") | R35: 50 | S35: 마스터_품목
A36: 고압 | B36: 히터 트랜스 | C36: ADX6000 | D36: 센더스트 코어 작업完 | G36: O | I36: =IFERROR(IF(OR($F36="O",$G36="O",$H36="O"),CHOOSE(MATCH($A36,{"튜브","고압","진공","튜닝","조립","출하"},0),"T","H","V","N","A","P")&IF($F36="O","R",IF($G36="O","A",IF($H36="O","F",""))),""),"") | L36: O | P36: =IF($I36="","",IF($J36="O","3","")&IF($K36="O","4","")&IF($L36="O","6","")&IF($M36="O","7","")&IF($N36="O","8","")&IF($O36="O","?","")&IF(OR($J36="O",$K36="O",$L36="O",$M36="O",$N36="O",$O36="O"),"-","")&$I36) | Q36: =HYPERLINK("#'마스터_품목'!A51","→ 마스터 R51") | R36: 51 | S36: 마스터_품목
A37: 고압 | B37: 트랜스포머 | C37: DX3000, ADX4000W | D37: 트랜스포머 | E37: 트랜스포머 (60kV) [DX3000, ADX4000W] | F37: O | I37: =IFERROR(IF(OR($F37="O",$G37="O",$H37="O"),CHOOSE(MATCH($A37,{"튜브","고압","진공","튜닝","조립","출하"},0),"T","H","V","N","A","P")&IF($F37="O","R",IF($G37="O","A",IF($H37="O","F",""))),""),"") | J37: O | K37: O | P37: =IF($I37="","",IF($J37="O","3","")&IF($K37="O","4","")&IF($L37="O","6","")&IF($M37="O","7","")&IF($N37="O","8","")&IF($O37="O","?","")&IF(OR($J37="O",$K37="O",$L37="O",$M37="O",$N37="O",$O37="O"),"-","")&$I37) | Q37: =HYPERLINK("#'마스터_품목'!A52","→ 마스터 R52") | R37: 52 | S37: 마스터_품목
A38: 고압 | B38: 트랜스포머 | C38: COCOON | D38: 트랜스포머 | E38: 트랜스포머 (70kV) [COCOON] | F38: O | I38: =IFERROR(IF(OR($F38="O",$G38="O",$H38="O"),CHOOSE(MATCH($A38,{"튜브","고압","진공","튜닝","조립","출하"},0),"T","H","V","N","A","P")&IF($F38="O","R",IF($G38="O","A",IF($H38="O","F",""))),""),"") | M38: O | P38: =IF($I38="","",IF($J38="O","3","")&IF($K38="O","4","")&IF($L38="O","6","")&IF($M38="O","7","")&IF($N38="O","8","")&IF($O38="O","?","")&IF(OR($J38="O",$K38="O",$L38="O",$M38="O",$N38="O",$O38="O"),"-","")&$I38) | Q38: =HYPERLINK("#'마스터_품목'!A53","→ 마스터 R53") | R38: 53 | S38: 마스터_품목
A39: 고압 | B39: 트랜스포머 | C39: SOLO | D39: 트랜스포머 | F39: O | I39: =IFERROR(IF(OR($F39="O",$G39="O",$H39="O"),CHOOSE(MATCH($A39,{"튜브","고압","진공","튜닝","조립","출하"},0),"T","H","V","N","A","P")&IF($F39="O","R",IF($G39="O","A",IF($H39="O","F",""))),""),"") | N39: O | P39: =IF($I39="","",IF($J39="O","3","")&IF($K39="O","4","")&IF($L39="O","6","")&IF($M39="O","7","")&IF($N39="O","8","")&IF($O39="O","?","")&IF(OR($J39="O",$K39="O",$L39="O",$M39="O",$N39="O",$O39="O"),"-","")&$I39) | Q39: =HYPERLINK("#'마스터_품목'!A54","→ 마스터 R54") | R39: 54 | S39: 마스터_품목
A40: 고압 | B40: 트랜스포머 | C40: ADX6000 | D40: 트랜스포머 | E40: 트랜스포머 (800턴) (80kV) [ADX6000] | F40: O | I40: =IFERROR(IF(OR($F40="O",$G40="O",$H40="O"),CHOOSE(MATCH($A40,{"튜브","고압","진공","튜닝","조립","출하"},0),"T","H","V","N","A","P")&IF($F40="O","R",IF($G40="O","A",IF($H40="O","F",""))),""),"") | L40: O | P40: =IF($I40="","",IF($J40="O","3","")&IF($K40="O","4","")&IF($L40="O","6","")&IF($M40="O","7","")&IF($N40="O","8","")&IF($O40="O","?","")&IF(OR($J40="O",$K40="O",$L40="O",$M40="O",$N40="O",$O40="O"),"-","")&$I40) | Q40: =HYPERLINK("#'마스터_품목'!A55","→ 마스터 R55") | R40: 55 | S40: 마스터_품목
...

Sheet 조립자재_재고현황
A1: 부서 | B1: 분류 | C1: 모델 | D1: 품목 | E1: ▼ 창고 품명 (창고파일에서 복사→붙여넣기) | F1: 원자재 | G1: 반제품 | H1: 완제품 | I1: 코드 | J1: 3 (DX3000) | K1: 4 (ADX4000W) | L1: 6 (ADX6000FB) | M1: 7 (COCOON) | N1: 8 (SOLO) | O1: ? (신제품) | P1: ERP 코드 {모델}-{공정} | Q1: 바로가기 (마스터로) | R1: 마스터행 | S1: 마스터시트
A2: 조립 | B2: 판넬 | C2: DX3000 | D2: 2.35" LCD 판넬 | E2: LCD PANEL (2.35"LCD) [DX3000] | F2: O | I2: =IFERROR(IF(OR($F2="O",$G2="O",$H2="O"),CHOOSE(MATCH($A2,{"튜브","고압","진공","튜닝","조립","출하"},0),"T","H","V","N","A","P")&IF($F2="O","R",IF($G2="O","A",IF($H2="O","F",""))),""),"") | J2: O | P2: =IF($I2="","",IF($J2="O","3","")&IF($K2="O","4","")&IF($L2="O","6","")&IF($M2="O","7","")&IF($N2="O","8","")&IF($O2="O","?","")&IF(OR($J2="O",$K2="O",$L2="O",$M2="O",$N2="O",$O2="O"),"-","")&$I2) | Q2: =HYPERLINK("#'마스터_품목'!A178","→ 마스터 R178") | R2: 178 | S2: 마스터_품목
A3: 조립 | B3: 판넬 | C3: DX3000 | D3: 2.4" TFT LCD 판넬 | E3: TFT LCD PANEL (2.4"LCD - CT1715N241A) [DX3000, SOLO] | F3: O | I3: =IFERROR(IF(OR($F3="O",$G3="O",$H3="O"),CHOOSE(MATCH($A3,{"튜브","고압","진공","튜닝","조립","출하"},0),"T","H","V","N","A","P")&IF($F3="O","R",IF($G3="O","A",IF($H3="O","F",""))),""),"") | J3: O | N3: O | P3: =IF($I3="","",IF($J3="O","3","")&IF($K3="O","4","")&IF($L3="O","6","")&IF($M3="O","7","")&IF($N3="O","8","")&IF($O3="O","?","")&IF(OR($J3="O",$K3="O",$L3="O",$M3="O",$N3="O",$O3="O"),"-","")&$I3) | Q3: =HYPERLINK("#'마스터_품목'!A179","→ 마스터 R179") | R3: 179 | S3: 마스터_품목
A4: 조립 | B4: 사출 및 공용 자재 | C4: DX3000 | D4: LCD GUIDE | E4: LCD GUIDE (ABS 난연 화이트) [DX3000] | F4: O | I4: =IFERROR(IF(OR($F4="O",$G4="O",$H4="O"),CHOOSE(MATCH($A4,{"튜브","고압","진공","튜닝","조립","출하"},0),"T","H","V","N","A","P")&IF($F4="O","R",IF($G4="O","A",IF($H4="O","F",""))),""),"") | J4: O | P4: =IF($I4="","",IF($J4="O","3","")&IF($K4="O","4","")&IF($L4="O","6","")&IF($M4="O","7","")&IF($N4="O","8","")&IF($O4="O","?","")&IF(OR($J4="O",$K4="O",$L4="O",$M4="O",$N4="O",$O4="O"),"-","")&$I4) | Q4: =HYPERLINK("#'마스터_품목'!A180","→ 마스터 R180") | R4: 180 | S4: 마스터_품목
A5: 조립 | B5: 사출 및 공용 자재 | C5: DX3000 | D5: NAVI KEY | E5: NAVI KEY (ABS 난연 화이트 + 밝은 회색) [DX3000] | F5: O | I5: =IFERROR(IF(OR($F5="O",$G5="O",$H5="O"),CHOOSE(MATCH($A5,{"튜브","고압","진공","튜닝","조립","출하"},0),"T","H","V","N","A","P")&IF($F5="O","R",IF($G5="O","A",IF($H5="O","F",""))),""),"") | J5: O | P5: =IF($I5="","",IF($J5="O","3","")&IF($K5="O","4","")&IF($L5="O","6","")&IF($M5="O","7","")&IF($N5="O","8","")&IF($O5="O","?","")&IF(OR($J5="O",$K5="O",$L5="O",$M5="O",$N5="O",$O5="O"),"-","")&$I5) | Q5: =HYPERLINK("#'마스터_품목'!A181","→ 마스터 R181") | R5: 181 | S5: 마스터_품목
A6: 조립 | B6: 사출 및 공용 자재 | C6: DX3000 | D6: POWER LED | E6: POWER LED (확산 아크릴) [DX3000] | F6: O | I6: =IFERROR(IF(OR($F6="O",$G6="O",$H6="O"),CHOOSE(MATCH($A6,{"튜브","고압","진공","튜닝","조립","출하"},0),"T","H","V","N","A","P")&IF($F6="O","R",IF($G6="O","A",IF($H6="O","F",""))),""),"") | J6: O | P6: =IF($I6="","",IF($J6="O","3","")&IF($K6="O","4","")&IF($L6="O","6","")&IF($M6="O","7","")&IF($N6="O","8","")&IF($O6="O","?","")&IF(OR($J6="O",$K6="O",$L6="O",$M6="O",$N6="O",$O6="O"),"-","")&$I6) | Q6: =HYPERLINK("#'마스터_품목'!A182","→ 마스터 R182") | R6: 182 | S6: 마스터_품목
A7: 조립 | B7: 사출 및 공용 자재 | C7: DX3000 | D7: POWER BUTTON | E7: POWER BUTTON (ABS 난연 화이트 + 밝은 회색) [DX3000] | F7: O | I7: =IFERROR(IF(OR($F7="O",$G7="O",$H7="O"),CHOOSE(MATCH($A7,{"튜브","고압","진공","튜닝","조립","출하"},0),"T","H","V","N","A","P")&IF($F7="O","R",IF($G7="O","A",IF($H7="O","F",""))),""),"") | J7: O | P7: =IF($I7="","",IF($J7="O","3","")&IF($K7="O","4","")&IF($L7="O","6","")&IF($M7="O","7","")&IF($N7="O","8","")&IF($O7="O","?","")&IF(OR($J7="O",$K7="O",$L7="O",$M7="O",$N7="O",$O7="O"),"-","")&$I7) | Q7: =HYPERLINK("#'마스터_품목'!A183","→ 마스터 R183") | R7: 183 | S7: 마스터_품목
A8: 조립 | B8: 사출 및 공용 자재 | C8: DX3000블랙 | D8: FRONT COVER (듀얼 슬라이드) | E8: FRONT COVER (듀얼 슬라이드) (ABS 난연 블랙) [DX3000] | F8: O | I8: =IFERROR(IF(OR($F8="O",$G8="O",$H8="O"),CHOOSE(MATCH($A8,{"튜브","고압","진공","튜닝","조립","출하"},0),"T","H","V","N","A","P")&IF($F8="O","R",IF($G8="O","A",IF($H8="O","F",""))),""),"") | J8: O | P8: =IF($I8="","",IF($J8="O","3","")&IF($K8="O","4","")&IF($L8="O","6","")&IF($M8="O","7","")&IF($N8="O","8","")&IF($O8="O","?","")&IF(OR($J8="O",$K8="O",$L8="O",$M8="O",$N8="O",$O8="O"),"-","")&$I8) | Q8: =HYPERLINK("#'마스터_품목'!A184","→ 마스터 R184") | R8: 184 | S8: 마스터_품목
A9: 조립 | B9: 사출 및 공용 자재 | C9: DX3000 화이트 | D9: FRONT COVER (듀얼 슬라이드) | E9: FRONT COVER (듀얼 슬라이드) (ABS 난연 화이트) [DX3000] | F9: O | I9: =IFERROR(IF(OR($F9="O",$G9="O",$H9="O"),CHOOSE(MATCH($A9,{"튜브","고압","진공","튜닝","조립","출하"},0),"T","H","V","N","A","P")&IF($F9="O","R",IF($G9="O","A",IF($H9="O","F",""))),""),"") | J9: O | P9: =IF($I9="","",IF($J9="O","3","")&IF($K9="O","4","")&IF($L9="O","6","")&IF($M9="O","7","")&IF($N9="O","8","")&IF($O9="O","?","")&IF(OR($J9="O",$K9="O",$L9="O",$M9="O",$N9="O",$O9="O"),"-","")&$I9) | Q9: =HYPERLINK("#'마스터_품목'!A185","→ 마스터 R185") | R9: 185 | S9: 마스터_품목
A10: 조립 | B10: 사출 및 공용 자재 | C10: DX3000 블랙 | D10: REAR COVER | E10: REAR COVER (ABS 난연 블랙) [DX3000] | F10: O | I10: =IFERROR(IF(OR($F10="O",$G10="O",$H10="O"),CHOOSE(MATCH($A10,{"튜브","고압","진공","튜닝","조립","출하"},0),"T","H","V","N","A","P")&IF($F10="O","R",IF($G10="O","A",IF($H10="O","F",""))),""),"") | J10: O | P10: =IF($I10="","",IF($J10="O","3","")&IF($K10="O","4","")&IF($L10="O","6","")&IF($M10="O","7","")&IF($N10="O","8","")&IF($O10="O","?","")&IF(OR($J10="O",$K10="O",$L10="O",$M10="O",$N10="O",$O10="O"),"-","")&$I10) | Q10: =HYPERLINK("#'마스터_품목'!A186","→ 마스터 R186") | R10: 186 | S10: 마스터_품목
A11: 조립 | B11: 사출 및 공용 자재 | C11: DX3000 화이트 | D11: REAR COVER | E11: REAR COVER (ABS 난연 화이트) [DX3000] | F11: O | I11: =IFERROR(IF(OR($F11="O",$G11="O",$H11="O"),CHOOSE(MATCH($A11,{"튜브","고압","진공","튜닝","조립","출하"},0),"T","H","V","N","A","P")&IF($F11="O","R",IF($G11="O","A",IF($H11="O","F",""))),""),"") | J11: O | P11: =IF($I11="","",IF($J11="O","3","")&IF($K11="O","4","")&IF($L11="O","6","")&IF($M11="O","7","")&IF($N11="O","8","")&IF($O11="O","?","")&IF(OR($J11="O",$K11="O",$L11="O",$M11="O",$N11="O",$O11="O"),"-","")&$I11) | Q11: =HYPERLINK("#'마스터_품목'!A187","→ 마스터 R187") | R11: 187 | S11: 마스터_품목
A12: 조립 | B12: 사출 및 공용 자재 | C12: DX3000 | D12: LCD LED | E12: LCD LED (확산 아크릴) [DX3000] | F12: O | I12: =IFERROR(IF(OR($F12="O",$G12="O",$H12="O"),CHOOSE(MATCH($A12,{"튜브","고압","진공","튜닝","조립","출하"},0),"T","H","V","N","A","P")&IF($F12="O","R",IF($G12="O","A",IF($H12="O","F",""))),""),"") | J12: O | P12: =IF($I12="","",IF($J12="O","3","")&IF($K12="O","4","")&IF($L12="O","6","")&IF($M12="O","7","")&IF($N12="O","8","")&IF($O12="O","?","")&IF(OR($J12="O",$K12="O",$L12="O",$M12="O",$N12="O",$O12="O"),"-","")&$I12) | Q12: =HYPERLINK("#'마스터_품목'!A188","→ 마스터 R188") | R12: 188 | S12: 마스터_품목
A13: 조립 | B13: 사출 및 공용 자재 | C13: DX3000 | D13: EX LED (왼쪽) | E13: EX LED (좌) (확산 아크릴) [DX3000] | F13: O | I13: =IFERROR(IF(OR($F13="O",$G13="O",$H13="O"),CHOOSE(MATCH($A13,{"튜브","고압","진공","튜닝","조립","출하"},0),"T","H","V","N","A","P")&IF($F13="O","R",IF($G13="O","A",IF($H13="O","F",""))),""),"") | J13: O | P13: =IF($I13="","",IF($J13="O","3","")&IF($K13="O","4","")&IF($L13="O","6","")&IF($M13="O","7","")&IF($N13="O","8","")&IF($O13="O","?","")&IF(OR($J13="O",$K13="O",$L13="O",$M13="O",$N13="O",$O13="O"),"-","")&$I13) | Q13: =HYPERLINK("#'마스터_품목'!A189","→ 마스터 R189") | R13: 189 | S13: 마스터_품목
A14: 조립 | B14: 사출 및 공용 자재 | C14: DX3000 | D14: EX LED (오른쪽) | E14: EX LED (우) (확산 아크릴) [DX3000] | F14: O | I14: =IFERROR(IF(OR($F14="O",$G14="O",$H14="O"),CHOOSE(MATCH($A14,{"튜브","고압","진공","튜닝","조립","출하"},0),"T","H","V","N","A","P")&IF($F14="O","R",IF($G14="O","A",IF($H14="O","F",""))),""),"") | J14: O | P14: =IF($I14="","",IF($J14="O","3","")&IF($K14="O","4","")&IF($L14="O","6","")&IF($M14="O","7","")&IF($N14="O","8","")&IF($O14="O","?","")&IF(OR($J14="O",$K14="O",$L14="O",$M14="O",$N14="O",$O14="O"),"-","")&$I14) | Q14: =HYPERLINK("#'마스터_품목'!A190","→ 마스터 R190") | R14: 190 | S14: 마스터_품목
A15: 조립 | B15: 사출 및 공용 자재 | C15: DX3000 | D15: EX BUTTON (개당 두개씩) | E15: EX BUTTON (ABS 난연 화이트 + 밝은 회색) [DX3000] | F15: O | I15: =IFERROR(IF(OR($F15="O",$G15="O",$H15="O"),CHOOSE(MATCH($A15,{"튜브","고압","진공","튜닝","조립","출하"},0),"T","H","V","N","A","P")&IF($F15="O","R",IF($G15="O","A",IF($H15="O","F",""))),""),"") | J15: O | P15: =IF($I15="","",IF($J15="O","3","")&IF($K15="O","4","")&IF($L15="O","6","")&IF($M15="O","7","")&IF($N15="O","8","")&IF($O15="O","?","")&IF(OR($J15="O",$K15="O",$L15="O",$M15="O",$N15="O",$O15="O"),"-","")&$I15) | Q15: =HYPERLINK("#'마스터_품목'!A191","→ 마스터 R191") | R15: 191 | S15: 마스터_품목
A16: 조립 | B16: 사출 및 공용 자재 | C16: DX3000 | D16: HAND STRAP | E16: HAND STRAP 손잡이 (인조 가죽) [DX3000] | F16: O | I16: =IFERROR(IF(OR($F16="O",$G16="O",$H16="O"),CHOOSE(MATCH($A16,{"튜브","고압","진공","튜닝","조립","출하"},0),"T","H","V","N","A","P")&IF($F16="O","R",IF($G16="O","A",IF($H16="O","F",""))),""),"") | J16: O | P16: =IF($I16="","",IF($J16="O","3","")&IF($K16="O","4","")&IF($L16="O","6","")&IF($M16="O","7","")&IF($N16="O","8","")&IF($O16="O","?","")&IF(OR($J16="O",$K16="O",$L16="O",$M16="O",$N16="O",$O16="O"),"-","")&$I16) | Q16: =HYPERLINK("#'마스터_품목'!A192","→ 마스터 R192") | R16: 192 | S16: 마스터_품목
A17: 조립 | B17: 사출 및 공용 자재 | C17: DX3000 | D17: HAND STRAP_로고없음_사파리,이미지웍스용 | E17: HAND STRAP 손잡이 (로고 없음) (인조 가죽) [DX3000] | F17: O | I17: =IFERROR(IF(OR($F17="O",$G17="O",$H17="O"),CHOOSE(MATCH($A17,{"튜브","고압","진공","튜닝","조립","출하"},0),"T","H","V","N","A","P")&IF($F17="O","R",IF($G17="O","A",IF($H17="O","F",""))),""),"") | J17: O | P17: =IF($I17="","",IF($J17="O","3","")&IF($K17="O","4","")&IF($L17="O","6","")&IF($M17="O","7","")&IF($N17="O","8","")&IF($O17="O","?","")&IF(OR($J17="O",$K17="O",$L17="O",$M17="O",$N17="O",$O17="O"),"-","")&$I17) | Q17: =HYPERLINK("#'마스터_품목'!A193","→ 마스터 R193") | R17: 193 | S17: 마스터_품목
A18: 조립 | B18: 사출 및 공용 자재 | C18: DX3000 화이트 | D18: 20cm CONE | E18: 20cm CONE (ABS 난연 화이트) [DX3000] | F18: O | I18: =IFERROR(IF(OR($F18="O",$G18="O",$H18="O"),CHOOSE(MATCH($A18,{"튜브","고압","진공","튜닝","조립","출하"},0),"T","H","V","N","A","P")&IF($F18="O","R",IF($G18="O","A",IF($H18="O","F",""))),""),"") | J18: O | P18: =IF($I18="","",IF($J18="O","3","")&IF($K18="O","4","")&IF($L18="O","6","")&IF($M18="O","7","")&IF($N18="O","8","")&IF($O18="O","?","")&IF(OR($J18="O",$K18="O",$L18="O",$M18="O",$N18="O",$O18="O"),"-","")&$I18) | Q18: =HYPERLINK("#'마스터_품목'!A194","→ 마스터 R194") | R18: 194 | S18: 마스터_품목
A19: 조립 | B19: 사출 및 공용 자재 | C19: DX3000 블랙 | D19: 20cm CONE | E19: 20cm CONE (ABS 난연 블랙 + 블랙 무광) [DX3000] | F19: O | I19: =IFERROR(IF(OR($F19="O",$G19="O",$H19="O"),CHOOSE(MATCH($A19,{"튜브","고압","진공","튜닝","조립","출하"},0),"T","H","V","N","A","P")&IF($F19="O","R",IF($G19="O","A",IF($H19="O","F",""))),""),"") | J19: O | P19: =IF($I19="","",IF($J19="O","3","")&IF($K19="O","4","")&IF($L19="O","6","")&IF($M19="O","7","")&IF($N19="O","8","")&IF($O19="O","?","")&IF(OR($J19="O",$K19="O",$L19="O",$M19="O",$N19="O",$O19="O"),"-","")&$I19) | Q19: =HYPERLINK("#'마스터_품목'!A195","→ 마스터 R195") | R19: 195 | S19: 마스터_품목
A20: 조립 | B20: 사출 및 공용 자재 | C20: DX3000 화이트 | D20: 15cm CONE | E20: 15cm CONE (ABS 난연 화이트) [DX3000] | F20: O | I20: =IFERROR(IF(OR($F20="O",$G20="O",$H20="O"),CHOOSE(MATCH($A20,{"튜브","고압","진공","튜닝","조립","출하"},0),"T","H","V","N","A","P")&IF($F20="O","R",IF($G20="O","A",IF($H20="O","F",""))),""),"") | J20: O | P20: =IF($I20="","",IF($J20="O","3","")&IF($K20="O","4","")&IF($L20="O","6","")&IF($M20="O","7","")&IF($N20="O","8","")&IF($O20="O","?","")&IF(OR($J20="O",$K20="O",$L20="O",$M20="O",$N20="O",$O20="O"),"-","")&$I20) | Q20: =HYPERLINK("#'마스터_품목'!A196","→ 마스터 R196") | R20: 196 | S20: 마스터_품목
A21: 조립 | B21: 사출 및 공용 자재 | C21: DX3000 | D21: X-CAP (기본) | E21: X-CAP (기본) (ABS 화이트 + 진한 회색) [DX3000] | F21: O | I21: =IFERROR(IF(OR($F21="O",$G21="O",$H21="O"),CHOOSE(MATCH($A21,{"튜브","고압","진공","튜닝","조립","출하"},0),"T","H","V","N","A","P")&IF($F21="O","R",IF($G21="O","A",IF($H21="O","F",""))),""),"") | J21: O | P21: =IF($I21="","",IF($J21="O","3","")&IF($K21="O","4","")&IF($L21="O","6","")&IF($M21="O","7","")&IF($N21="O","8","")&IF($O21="O","?","")&IF(OR($J21="O",$K21="O",$L21="O",$M21="O",$N21="O",$O21="O"),"-","")&$I21) | Q21: =HYPERLINK("#'마스터_품목'!A197","→ 마스터 R197") | R21: 197 | S21: 마스터_품목
A22: 조립 | B22: 사출 및 공용 자재 | C22: DX3000 ADX4000W | D22: X-CAP 체결형 (신형) | E22: X-CAP 체결형 (신형) (ABS 난연 화이트 + 진한 회색) [DX3000] | F22: O | I22: =IFERROR(IF(OR($F22="O",$G22="O",$H22="O"),CHOOSE(MATCH($A22,{"튜브","고압","진공","튜닝","조립","출하"},0),"T","H","V","N","A","P")&IF($F22="O","R",IF($G22="O","A",IF($H22="O","F",""))),""),"") | J22: O | K22: O | P22: =IF($I22="","",IF($J22="O","3","")&IF($K22="O","4","")&IF($L22="O","6","")&IF($M22="O","7","")&IF($N22="O","8","")&IF($O22="O","?","")&IF(OR($J22="O",$K22="O",$L22="O",$M22="O",$N22="O",$O22="O"),"-","")&$I22) | Q22: =HYPERLINK("#'마스터_품목'!A198","→ 마스터 R198") | R22: 198 | S22: 마스터_품목
A23: 조립 | B23: 사출 및 공용 자재 | C23: DX3000 ADX4000W | D23: 가죽손잡이 고리1_ [AL(Cr도금), SUS Φ2.0] | E23: 고리 1 (니켈 도금) [DX3000, ADX4000W] | F23: O | I23: =IFERROR(IF(OR($F23="O",$G23="O",$H23="O"),CHOOSE(MATCH($A23,{"튜브","고압","진공","튜닝","조립","출하"},0),"T","H","V","N","A","P")&IF($F23="O","R",IF($G23="O","A",IF($H23="O","F",""))),""),"") | J23: O | K23: O | P23: =IF($I23="","",IF($J23="O","3","")&IF($K23="O","4","")&IF($L23="O","6","")&IF($M23="O","7","")&IF($N23="O","8","")&IF($O23="O","?","")&IF(OR($J23="O",$K23="O",$L23="O",$M23="O",$N23="O",$O23="O"),"-","")&$I23) | Q23: =HYPERLINK("#'마스터_품목'!A199","→ 마스터 R199") | R23: 199 | S23: 마스터_품목
A24: 조립 | B24: 사출 및 공용 자재 | C24: DX3000 ADX4000W | D24: 가죽손잡이 고리2_ [AL(Cr도금), SUS Φ2.0 ] | E24: 고리 2 (니켈 도금) [DX3000] | F24: O | I24: =IFERROR(IF(OR($F24="O",$G24="O",$H24="O"),CHOOSE(MATCH($A24,{"튜브","고압","진공","튜닝","조립","출하"},0),"T","H","V","N","A","P")&IF($F24="O","R",IF($G24="O","A",IF($H24="O","F",""))),""),"") | J24: O | P24: =IF($I24="","",IF($J24="O","3","")&IF($K24="O","4","")&IF($L24="O","6","")&IF($M24="O","7","")&IF($N24="O","8","")&IF($O24="O","?","")&IF(OR($J24="O",$K24="O",$L24="O",$M24="O",$N24="O",$O24="O"),"-","")&$I24) | Q24: =HYPERLINK("#'마스터_품목'!A200","→ 마스터 R200") | R24: 200 | S24: 마스터_품목
A25: 조립 | B25: 사출 및 공용 자재 | C25: DX3000 | D25: LCD 윈도우 | E25: LCD WINDOW (투명 아크릴) [DX3000] | F25: O | I25: =IFERROR(IF(OR($F25="O",$G25="O",$H25="O"),CHOOSE(MATCH($A25,{"튜브","고압","진공","튜닝","조립","출하"},0),"T","H","V","N","A","P")&IF($F25="O","R",IF($G25="O","A",IF($H25="O","F",""))),""),"") | J25: O | P25: =IF($I25="","",IF($J25="O","3","")&IF($K25="O","4","")&IF($L25="O","6","")&IF($M25="O","7","")&IF($N25="O","8","")&IF($O25="O","?","")&IF(OR($J25="O",$K25="O",$L25="O",$M25="O",$N25="O",$O25="O"),"-","")&$I25) | Q25: =HYPERLINK("#'마스터_품목'!A201","→ 마스터 R201") | R25: 201 | S25: 마스터_품목
A26: 조립 | B26: 사출 및 공용 자재 | C26: DX3000 회색 | D26: 배터리커버 | E26: BATTERY COVER (ABS 난연 화이트 + 진한 회색) [DX3000] | F26: O | I26: =IFERROR(IF(OR($F26="O",$G26="O",$H26="O"),CHOOSE(MATCH($A26,{"튜브","고압","진공","튜닝","조립","출하"},0),"T","H","V","N","A","P")&IF($F26="O","R",IF($G26="O","A",IF($H26="O","F",""))),""),"") | J26: O | P26: =IF($I26="","",IF($J26="O","3","")&IF($K26="O","4","")&IF($L26="O","6","")&IF($M26="O","7","")&IF($N26="O","8","")&IF($O26="O","?","")&IF(OR($J26="O",$K26="O",$L26="O",$M26="O",$N26="O",$O26="O"),"-","")&$I26) | Q26: =HYPERLINK("#'마스터_품목'!A202","→ 마스터 R202") | R26: 202 | S26: 마스터_품목
A27: 조립 | B27: 사출 및 공용 자재 | C27: DX3000 블랙 | D27: 배터리커버 | E27: BATTERY COVER (ABS 난연 블랙 + 블랙) [DX3000] | F27: O | I27: =IFERROR(IF(OR($F27="O",$G27="O",$H27="O"),CHOOSE(MATCH($A27,{"튜브","고압","진공","튜닝","조립","출하"},0),"T","H","V","N","A","P")&IF($F27="O","R",IF($G27="O","A",IF($H27="O","F",""))),""),"") | J27: O | P27: =IF($I27="","",IF($J27="O","3","")&IF($K27="O","4","")&IF($L27="O","6","")&IF($M27="O","7","")&IF($N27="O","8","")&IF($O27="O","?","")&IF(OR($J27="O",$K27="O",$L27="O",$M27="O",$N27="O",$O27="O"),"-","")&$I27) | Q27: =HYPERLINK("#'마스터_품목'!A203","→ 마스터 R203") | R27: 203 | S27: 마스터_품목
A28: 조립 | B28: 사출 및 공용 자재 | C28: DX3000 | D28: 데코가이드 | E28: DECO GUIDE (ABS 난연 화이트 + 진한 회색) [DX3000] | F28: O | I28: =IFERROR(IF(OR($F28="O",$G28="O",$H28="O"),CHOOSE(MATCH($A28,{"튜브","고압","진공","튜닝","조립","출하"},0),"T","H","V","N","A","P")&IF($F28="O","R",IF($G28="O","A",IF($H28="O","F",""))),""),"") | J28: O | P28: =IF($I28="","",IF($J28="O","3","")&IF($K28="O","4","")&IF($L28="O","6","")&IF($M28="O","7","")&IF($N28="O","8","")&IF($O28="O","?","")&IF(OR($J28="O",$K28="O",$L28="O",$M28="O",$N28="O",$O28="O"),"-","")&$I28) | Q28: =HYPERLINK("#'마스터_품목'!A204","→ 마스터 R204") | R28: 204 | S28: 마스터_품목
A29: 조립 | B29: 사출 및 공용 자재 | C29: DX3000 | D29: 알루미늄 필터 [0.8T * Φ63] | E29: 알루미늄 필터 (0.8T * Φ63) [DX3000] | F29: O | I29: =IFERROR(IF(OR($F29="O",$G29="O",$H29="O"),CHOOSE(MATCH($A29,{"튜브","고압","진공","튜닝","조립","출하"},0),"T","H","V","N","A","P")&IF($F29="O","R",IF($G29="O","A",IF($H29="O","F",""))),""),"") | J29: O | K29: O | P29: =IF($I29="","",IF($J29="O","3","")&IF($K29="O","4","")&IF($L29="O","6","")&IF($M29="O","7","")&IF($N29="O","8","")&IF($O29="O","?","")&IF(OR($J29="O",$K29="O",$L29="O",$M29="O",$N29="O",$O29="O"),"-","")&$I29) | Q29: =HYPERLINK("#'마스터_품목'!A205","→ 마스터 R205") | R29: 205 | S29: 마스터_품목
A30: 조립 | B30: 하네스 | C30: DX3000 | D30: CJ4003 JACK (관전류 짹 + 2핀케이블) - 하네스8 | E30: 하네스 8번 (CJ4003 잭 (관전류 짹 + 2핀케이블)) [DX3000] | F30: O | I30: =IFERROR(IF(OR($F30="O",$G30="O",$H30="O"),CHOOSE(MATCH($A30,{"튜브","고압","진공","튜닝","조립","출하"},0),"T","H","V","N","A","P")&IF($F30="O","R",IF($G30="O","A",IF($H30="O","F",""))),""),"") | J30: O | P30: =IF($I30="","",IF($J30="O","3","")&IF($K30="O","4","")&IF($L30="O","6","")&IF($M30="O","7","")&IF($N30="O","8","")&IF($O30="O","?","")&IF(OR($J30="O",$K30="O",$L30="O",$M30="O",$N30="O",$O30="O"),"-","")&$I30) | Q30: =HYPERLINK("#'마스터_품목'!A206","→ 마스터 R206") | R30: 206 | S30: 마스터_품목
A31: 조립 | B31: 하네스 | C31: DX3000 | D31: FFC 20핀 - 하네스1 | E31: 하네스 1번 (FFC 20핀) [DX3000] | F31: O | I31: =IFERROR(IF(OR($F31="O",$G31="O",$H31="O"),CHOOSE(MATCH($A31,{"튜브","고압","진공","튜닝","조립","출하"},0),"T","H","V","N","A","P")&IF($F31="O","R",IF($G31="O","A",IF($H31="O","F",""))),""),"") | J31: O | P31: =IF($I31="","",IF($J31="O","3","")&IF($K31="O","4","")&IF($L31="O","6","")&IF($M31="O","7","")&IF($N31="O","8","")&IF($O31="O","?","")&IF(OR($J31="O",$K31="O",$L31="O",$M31="O",$N31="O",$O31="O"),"-","")&$I31) | Q31: =HYPERLINK("#'마스터_품목'!A207","→ 마스터 R207") | R31: 207 | S31: 마스터_품목
A32: 조립 | B32: 하네스 | C32: DX3000 | D32: EXP KEY 4핀 케이블 - 하네스5 (개당 2개씩) | E32: 하네스 5번 (EXP KEY 4핀 케이블) [DX3000] | F32: O | I32: =IFERROR(IF(OR($F32="O",$G32="O",$H32="O"),CHOOSE(MATCH($A32,{"튜브","고압","진공","튜닝","조립","출하"},0),"T","H","V","N","A","P")&IF($F32="O","R",IF($G32="O","A",IF($H32="O","F",""))),""),"") | J32: O | P32: =IF($I32="","",IF($J32="O","3","")&IF($K32="O","4","")&IF($L32="O","6","")&IF($M32="O","7","")&IF($N32="O","8","")&IF($O32="O","?","")&IF(OR($J32="O",$K32="O",$L32="O",$M32="O",$N32="O",$O32="O"),"-","")&$I32) | Q32: =HYPERLINK("#'마스터_품목'!A208","→ 마스터 R208") | R32: 208 | S32: 마스터_품목
A33: 조립 | B33: 하네스 | C33: DX3000 | D33: EX BD (듀얼) - 왼쪽 | E33: EX B/D (듀얼) (좌) [DX3000] | F33: O | I33: =IFERROR(IF(OR($F33="O",$G33="O",$H33="O"),CHOOSE(MATCH($A33,{"튜브","고압","진공","튜닝","조립","출하"},0),"T","H","V","N","A","P")&IF($F33="O","R",IF($G33="O","A",IF($H33="O","F",""))),""),"") | J33: O | P33: =IF($I33="","",IF($J33="O","3","")&IF($K33="O","4","")&IF($L33="O","6","")&IF($M33="O","7","")&IF($N33="O","8","")&IF($O33="O","?","")&IF(OR($J33="O",$K33="O",$L33="O",$M33="O",$N33="O",$O33="O"),"-","")&$I33) | Q33: =HYPERLINK("#'마스터_품목'!A209","→ 마스터 R209") | R33: 209 | S33: 마스터_품목
A34: 조립 | B34: 하네스 | C34: DX3000 | D34: EX BD (듀얼) - 오른쪽 | E34: EX B/D (듀얼) (우) [DX3000] | F34: O | I34: =IFERROR(IF(OR($F34="O",$G34="O",$H34="O"),CHOOSE(MATCH($A34,{"튜브","고압","진공","튜닝","조립","출하"},0),"T","H","V","N","A","P")&IF($F34="O","R",IF($G34="O","A",IF($H34="O","F",""))),""),"") | J34: O | P34: =IF($I34="","",IF($J34="O","3","")&IF($K34="O","4","")&IF($L34="O","6","")&IF($M34="O","7","")&IF($N34="O","8","")&IF($O34="O","?","")&IF(OR($J34="O",$K34="O",$L34="O",$M34="O",$N34="O",$O34="O"),"-","")&$I34) | Q34: =HYPERLINK("#'마스터_품목'!A210","→ 마스터 R210") | R34: 210 | S34: 마스터_품목
A35: 조립 | B35: 하네스 | C35: DX3000 | D35: EX BD (원버턴) - 사파리 | E35: EX B/D 사파리 (원버턴) [DX3000] | F35: O | I35: =IFERROR(IF(OR($F35="O",$G35="O",$H35="O"),CHOOSE(MATCH($A35,{"튜브","고압","진공","튜닝","조립","출하"},0),"T","H","V","N","A","P")&IF($F35="O","R",IF($G35="O","A",IF($H35="O","F",""))),""),"") | J35: O | P35: =IF($I35="","",IF($J35="O","3","")&IF($K35="O","4","")&IF($L35="O","6","")&IF($M35="O","7","")&IF($N35="O","8","")&IF($O35="O","?","")&IF(OR($J35="O",$K35="O",$L35="O",$M35="O",$N35="O",$O35="O"),"-","")&$I35) | Q35: =HYPERLINK("#'마스터_품목'!A211","→ 마스터 R211") | R35: 211 | S35: 마스터_품목
A36: 조립 | B36: 하네스 | C36: DX3000 | D36: LCD BD | E36: LCD B/D (듀얼 슬라이드) [DX3000] | F36: O | I36: =IFERROR(IF(OR($F36="O",$G36="O",$H36="O"),CHOOSE(MATCH($A36,{"튜브","고압","진공","튜닝","조립","출하"},0),"T","H","V","N","A","P")&IF($F36="O","R",IF($G36="O","A",IF($H36="O","F",""))),""),"") | J36: O | P36: =IF($I36="","",IF($J36="O","3","")&IF($K36="O","4","")&IF($L36="O","6","")&IF($M36="O","7","")&IF($N36="O","8","")&IF($O36="O","?","")&IF(OR($J36="O",$K36="O",$L36="O",$M36="O",$N36="O",$O36="O"),"-","")&$I36) | Q36: =HYPERLINK("#'마스터_품목'!A212","→ 마스터 R212") | R36: 212 | S36: 마스터_품목
A37: 조립 | B37: 하네스 | C37: DX3000 | D37: LCD BD (사파리) -원버턴타입 | E37: LCD B/D (사파리) -원버턴타입 [DX3000] | F37: O | I37: =IFERROR(IF(OR($F37="O",$G37="O",$H37="O"),CHOOSE(MATCH($A37,{"튜브","고압","진공","튜닝","조립","출하"},0),"T","H","V","N","A","P")&IF($F37="O","R",IF($G37="O","A",IF($H37="O","F",""))),""),"") | J37: O | P37: =IF($I37="","",IF($J37="O","3","")&IF($K37="O","4","")&IF($L37="O","6","")&IF($M37="O","7","")&IF($N37="O","8","")&IF($O37="O","?","")&IF(OR($J37="O",$K37="O",$L37="O",$M37="O",$N37="O",$O37="O"),"-","")&$I37) | Q37: =HYPERLINK("#'마스터_품목'!A213","→ 마스터 R213") | R37: 213 | S37: 마스터_품목
A38: 조립 | B38: 하네스 | C38: DX3000 | D38: TFT LCD BD | E38: TFT LCD B/D (듀얼 슬라이드) (V3.0.1) [DX3000] | F38: O | I38: =IFERROR(IF(OR($F38="O",$G38="O",$H38="O"),CHOOSE(MATCH($A38,{"튜브","고압","진공","튜닝","조립","출하"},0),"T","H","V","N","A","P")&IF($F38="O","R",IF($G38="O","A",IF($H38="O","F",""))),""),"") | J38: O | P38: =IF($I38="","",IF($J38="O","3","")&IF($K38="O","4","")&IF($L38="O","6","")&IF($M38="O","7","")&IF($N38="O","8","")&IF($O38="O","?","")&IF(OR($J38="O",$K38="O",$L38="O",$M38="O",$N38="O",$O38="O"),"-","")&$I38) | Q38: =HYPERLINK("#'마스터_품목'!A214","→ 마스터 R214") | R38: 214 | S38: 마스터_품목
A39: 조립 | B39: 하네스 | C39: DX3000 | D39: LED DRIVE BD V3.0.1 (TFT CTR BD용) | E39: AIM LED 쪽 보드 (V3.0.1) [DX3000] | F39: O | I39: =IFERROR(IF(OR($F39="O",$G39="O",$H39="O"),CHOOSE(MATCH($A39,{"튜브","고압","진공","튜닝","조립","출하"},0),"T","H","V","N","A","P")&IF($F39="O","R",IF($G39="O","A",IF($H39="O","F",""))),""),"") | J39: O | P39: =IF($I39="","",IF($J39="O","3","")&IF($K39="O","4","")&IF($L39="O","6","")&IF($M39="O","7","")&IF($N39="O","8","")&IF($O39="O","?","")&IF(OR($J39="O",$K39="O",$L39="O",$M39="O",$N39="O",$O39="O"),"-","")&$I39) | Q39: =HYPERLINK("#'마스터_품목'!A215","→ 마스터 R215") | R39: 215 | S39: 마스터_품목
A40: 조립 | B40: ASS'Y | C40: DX3000 | D40: 데코가이드 ASS'Y (손잡이 포함) | G40: O | I40: =IFERROR(IF(OR($F40="O",$G40="O",$H40="O"),CHOOSE(MATCH($A40,{"튜브","고압","진공","튜닝","조립","출하"},0),"T","H","V","N","A","P")&IF($F40="O","R",IF($G40="O","A",IF($H40="O","F",""))),""),"") | J40: O | P40: =IF($I40="","",IF($J40="O","3","")&IF($K40="O","4","")&IF($L40="O","6","")&IF($M40="O","7","")&IF($N40="O","8","")&IF($O40="O","?","")&IF(OR($J40="O",$K40="O",$L40="O",$M40="O",$N40="O",$O40="O"),"-","")&$I40) | Q40: =HYPERLINK("#'마스터_품목'!A216","→ 마스터 R216") | R40: 216 | S40: 마스터_품목
...

Sheet 조립완제품_재고현황
A1: 부서 | B1: 분류 | C1: 모델 | D1: 품목 | E1: ▼ 창고 품명 (창고파일에서 복사→붙여넣기) | F1: 원자재 | G1: 반제품 | H1: 완제품 | I1: 코드 | J1: 3 (DX3000) | K1: 4 (ADX4000W) | L1: 6 (ADX6000FB) | M1: 7 (COCOON) | N1: 8 (SOLO) | O1: ? (신제품) | P1: ERP 코드 {모델}-{공정} | Q1: 바로가기 (마스터로) | R1: 마스터행 | S1: 마스터시트
A2: 조립 | B2: 완제품 본체 | C2: DX3000 | D2: 60kV 2mA / 10cm 기본 (Black) | H2: O | I2: =IFERROR(IF(OR($F2="O",$G2="O",$H2="O"),CHOOSE(MATCH($A2,{"튜브","고압","진공","튜닝","조립","출하"},0),"T","H","V","N","A","P")&IF($F2="O","R",IF($G2="O","A",IF($H2="O","F",""))),""),"") | J2: O | P2: =IF($I2="","",IF($J2="O","3","")&IF($K2="O","4","")&IF($L2="O","6","")&IF($M2="O","7","")&IF($N2="O","8","")&IF($O2="O","?","")&IF(OR($J2="O",$K2="O",$L2="O",$M2="O",$N2="O",$O2="O"),"-","")&$I2) | Q2: =HYPERLINK("#'마스터_품목'!A695","→ 마스터 R695") | R2: 695 | S2: 마스터_품목
