Workbook

Sheet 매칭_작업안내
B3: 📋 창고 품명 매칭 작업 안내
B5: ▶ 작업 목적
B6: 생산부 품목명과 창고 품목명이 달라서 자동 매칭이 안 됩니다.
B7: 담당자가 "같은 품목"을 직접 지정해주셔야 합니다.
B9: ▶ 작업 시트
B10: 다음 2개 시트의 E열(주황 헤더)에 창고 품명을 붙여넣으세요:
B11: ① 고압진공_재고현황
B12: ② 조립자재_재고현황
B14: ▶ 작업 방법 (단계별)
B15: STEP 1. 이 파일(생산부_재고)을 왼쪽 화면에 띄움
B16: STEP 2. 창고_재고 파일을 오른쪽 화면에 띄움
B17: STEP 3. 왼쪽에서 작업할 시트(예: 고압진공_재고현황)를 엶
... B44: → 최종적으로 생산부·창고 통합 마스터 데이터가 완성됩니다.

Sheet 고압진공_재고현황
A1: 부서 | B1: 분류 | C1: 모델 | D1: 품목 | E1: ▼ 창고 품명 (창고파일에서 복사→붙여넣기)
A2: 고압 | B2: 튜브 | C2: DX3000, ADX4000W | D2: 캐논튜브 [ D-081B ] _ 60KV
A3: 고압 | B3: 튜브 | C3: COCOON, SOLO | D3: 캐논튜브 [ D-041 ] _ 70KV
A4: 고압 | B4: 튜브 | C4: ADX6000 | D4: 캐논튜브 [ D-0813 ] _ 80KV
A5: 고압 | B5: 튜브 | C5: DX3000, ADX4000W, ADX6000, SOLO | D5: 세라믹튜브 [DXDR-070] _ 70KV
A6: 고압 | B6: 튜브 | C6: ADX6000 | D6: 세라믹튜브 [DXDR-100] _ 100KV
A7: 고압 | B7: 튜브 | C7: ADX6000 | D7: CEI튜브 [OX-70] _ 90KV
A8: 고압 | B8: 부품 | C8: DX3000, ADX4000W | D8: 고압다이오드 2CL77 [20KV, 5mA]
A9: 고압 | B9: 부품 | C9: DX3000, ADX4000W, COCOON | D9: 네온램프(NEON-5T)
A10: 고압 | B10: 부품 | C10: DX3000, ADX4000W, ADX6000 | D10: RK92-11XD307J (시멘트 저항)
A11: 고압 | B11: 부품 | C11: DX3000, ADX4000W | D11: 고압용 (30㏀)
A12: 고압 | B12: 부품 | C12: DX3000, ADX4000W, ADX6000 | D12: 고압용 (15㏀±1％, DIP) - 1/4W
A13: 고압 | B13: 부품 | C13: ADX6000 | D13: 고압용 (500Ω±1％, DIP) - 1/4W
... A50: 고압 | B50: BD | C50: SOLO | D50: 고압베어B/D (4개 1세트)
A51: 고압 | C51: COCOON | D51: 고압베어B/D (신형) (Ver. 2.12)
A52: 고압 | C52: COCOON | D52: 튜브 고정 지지대 (Ver 2.12에 사용)
A53: 고압 | C53: DX3000V | D53: 고압베어B/D (D-0813) (Ver 1.0.0)
A54: 고압 | B54: BD | C54: ADX6000 | D54: 튜브 고정 보드 에노드 (나사)
A55: 고압 | B55: BD | C55: ADX6000 | D55: 튜브 고정 보드 케소드 (필라멘트)
A56: 진공 | B56: BD | C56: DX3000, ADX4000W | D56: 7핀 BD [190*88*1.6T*2L]
A57: 진공 | B57: BD | C57: ADX6000 | D57: 8핀 BD
A58: 진공 | B58: BD | C58: ADX6000 | D58: 10핀 BD
A59: 진공 | B59: BD | C59: COCOON | D59: 8핀 BD
A60: 진공 | B60: BD | C60: DX3000 | D60: 9핀 BD
A61: 진공 | B61: BD | C61: SOLO | D61: 9핀 BD
A62: 진공 | B62: BD | C62: DX3000V | D62: 10핀 BD
A63: 진공 | B63: BD | C63: DX3000 | D63: D3CT (TFT용)
A64: 진공 | B64: BD | C64: DX3000 | D64: DC3D (유럽용)
A65: 진공 | B65: BD | C65: DX3000 | D65: D3CL (미국용)
... A83: 고압 | B83: 고압보드 A,SSY | C83: COCOON | D83: 고압보드SMT 完 [Ver 2.12 신형]
A84: 고압 | C84: SOLO | D84: 고압보드 SMT (DXDR-070)
A85: 고압 | C85: SOLO | D85: 고압보드 SMT (D-041)
A86: 고압 | C86: DX3000V | D86: 고압보드 SMT 完 (D-0813) (Ver 1.0.0)
A87: 고압 | B87: 신주 및 베크라이트 | C87: DX3000, ADX4000W, ADX6000 | D87: 베이클라이트 하우징 파이프
A88: 고압 | C88: COCOON, SOLO | D88: 70KV 튜브 하우징용 파이프
A89: 고압 | C89: SOLO | D89: DXDR-070 하우징용 파이프
A90: 고압 | C90: SOLO | D90: D-041 하우징용 파이프
A91: 고압 | C91: ADX6000 | D91: PE 하우징 파이프
A92: 진공 | B92: 신주 A,ssy | C92: DX3000, ADX4000W, ADX6000 | D92: 베크라이트케이스
A93: 진공 | C93: COCOON | D93: (nc)케이스
...

Sheet 조립자재_재고현황
A1: 부서 | B1: 분류 | C1: 모델 | D1: 품목 | E1: ▼ 창고 품명 (창고파일에서 복사→붙여넣기)
A2: 조립 | B2: 판넬 | C2: DX3000 | D2: 2.4" TFT LCD 판넬
A3: 조립 | B3: 사출 및 공용 자재 | C3: DX3000 | D3: LCD GUIDE
A4: 조립 | B4: 사출 및 공용 자재 | C4: DX3000 | D4: NAVI KEY
A5: 조립 | B5: 사출 및 공용 자재 | C5: DX3000 | D5: POWER LED
A6: 조립 | B6: 사출 및 공용 자재 | C6: DX3000 | D6: POWER BUTTON
A7: 조립 | B7: 사출 및 공용 자재 | C7: DX3000블랙 | D7: FRONT COVER (듀얼 슬라이드)
A8: 조립 | B8: 사출 및 공용 자재 | C8: DX3000 화이트 | D8: FRONT COVER (듀얼 슬라이드)
A9: 조립 | B9: 사출 및 공용 자재 | C9: DX3000 블랙 | D9: REAR COVER
A10: 조립 | B10: 사출 및 공용 자재 | C10: DX3000 화이트 | D10: REAR COVER
A11: 조립 | B11: 사출 및 공용 자재 | C11: DX3000 | D11: LCD LED
A12: 조립 | B12: 사출 및 공용 자재 | C12: DX3000 | D12: EX LED (왼쪽)
A13: 조립 | B13: 사출 및 공용 자재 | C13: DX3000 | D13: EX LED (오른쪽)
... A503: 조립 | B503: 하네스 | C503: SOLO | D503: Harness-05 ( Main PCB + 리모콘 BD 연결 3핀 )

Sheet 창고_재고현황
A1: 부서 | B1: 분류 | C1: 모델 | D1: 품목 | E1: 공급처 | G1: 생산부 품명 (자동 표시) | H1: 매칭순번
A2: 창고 | B2: 전극 | C2: DXDR-070 | D2: 전극(70kV) (순철 도금) [DXDR-070] | G2: =IFERROR("["&INDEX(고압진공_재고현황!$A:$A,MATCH($D2,고압진공_재고현황!$E:$E,0))&"] "&INDEX(고압진공_재고현황!$D:$D,MATCH($D2,고압진공_재고현황!$E:$E,0)),IFERROR("[조립] "&INDEX(조립자재_재고현황!$D:$D,MATCH($D2,조립자재_재고현황!$E:$E,0)),"")) | H2: =IF(G2="","",COUNTIF($G$2:G2,"?*"))
A3: 창고 | B3: 필라멘트 | C3: DXDR-070 | D3: 텅스텐 필라멘트 [DXDR-070] | G3: =IFERROR("["&INDEX(고압진공_재고현황!$A:$A,MATCH($D3,고압진공_재고현황!$E:$E,0))&"] "&INDEX(고압진공_재고현황!$D:$D,MATCH($D3,고압진공_재고현황!$E:$E,0)),IFERROR("[조립] "&INDEX(조립자재_재고현황!$D:$D,MATCH($D3,조립자재_재고현황!$E:$E,0)),"")) | H3: =IF(G3="","",COUNTIF($G$2:G3,"?*"))
A4: 창고 | B4: 게터 | C4: DXDR-070,DXDR-100 | D4: 게터 [DXDR-070,DXDR-100] | G4: =IFERROR("["&INDEX(고압진공_재고현황!$A:$A,MATCH($D4,고압진공_재고현황!$E:$E,0))&"] "&INDEX(고압진공_재고현황!$D:$D,MATCH($D4,고압진공_재고현황!$E:$E,0)),IFERROR("[조립] "&INDEX(조립자재_재고현황!$D:$D,MATCH($D4,조립자재_재고현황!$E:$E,0)),"")) | H4: =IF(G4="","",COUNTIF($G$2:G4,"?*"))
A5: 창고 | B5: 코바 | C5: DXDR-070 | D5: 에노드 [DXDR-070] | G5: =IFERROR("["&INDEX(고압진공_재고현황!$A:$A,MATCH($D5,고압진공_재고현황!$E:$E,0))&"] "&INDEX(고압진공_재고현황!$D:$D,MATCH($D5,고압진공_재고현황!$E:$E,0)),IFERROR("[조립] "&INDEX(조립자재_재고현황!$D:$D,MATCH($D5,조립자재_재고현황!$E:$E,0)),"")) | H5: =IF(G5="","",COUNTIF($G$2:G5,"?*"))
A6: 창고 | B6: 코바 | C6: DXDR-070 | D6: 포커서 [DXDR-070] | G6: =IFERROR("["&INDEX(고압진공_재고현황!$A:$A,MATCH($D6,고압진공_재고현황!$E:$E,0))&"] "&INDEX(고압진공_재고현황!$D:$D,MATCH($D6,고압진공_재고현황!$E:$E,0)),IFERROR("[조립] "&INDEX(조립자재_재고현황!$D:$D,MATCH($D6,조립자재_재고현황!$E:$E,0)),"")) | H6: =IF(G6="","",COUNTIF($G$2:G6,"?*"))
A7: 창고 | B7: 세라믹 | C7: DXDR-070 | D7: 세라믹 바디 [DXDR-070] | G7: =IFERROR("["&INDEX(고압진공_재고현황!$A:$A,MATCH($D7,고압진공_재고현황!$E:$E,0))&"] "&INDEX(고압진공_재고현황!$D:$D,MATCH($D7,고압진공_재고현황!$E:$E,0)),IFERROR("[조립] "&INDEX(조립자재_재고현황!$D:$D,MATCH($D7,조립자재_재고현황!$E:$E,0)),"")) | H7: =IF(G7="","",COUNTIF($G$2:G7,"?*"))
A8: 창고 | B8: 세라믹 | C8: DXDR-070 | D8: 세라믹 스템 [DXDR-070] | G8: =IFERROR("["&INDEX(고압진공_재고현황!$A:$A,MATCH($D8,고압진공_재고현황!$E:$E,0))&"] "&INDEX(고압진공_재고현황!$D:$D,MATCH($D8,고압진공_재고현황!$E:$E,0)),IFERROR("[조립] "&INDEX(조립자재_재고현황!$D:$D,MATCH($D8,조립자재_재고현황!$E:$E,0)),"")) | H8: =IF(G8="","",COUNTIF($G$2:G8,"?*"))
A9: 창고 | B9: 필러 | C9: DXDR-070 | D9: 필러 [DXDR-070] | G9: =IFERROR("["&INDEX(고압진공_재고현황!$A:$A,MATCH($D9,고압진공_재고현황!$E:$E,0))&"] "&INDEX(고압진공_재고현황!$D:$D,MATCH($D9,고압진공_재고현황!$E:$E,0)),IFERROR("[조립] "&INDEX(조립자재_재고현황!$D:$D,MATCH($D9,조립자재_재고현황!$E:$E,0)),"")) | H9: =IF(G9="","",COUNTIF($G$2:G9,"?*"))
A10: 창고 | B10: 필러 | C10: DXDR-070 | D10: 전극 필러 [DXDR-070] | G10: =IFERROR("["&INDEX(고압진공_재고현황!$A:$A,MATCH($D10,고압진공_재고현황!$E:$E,0))&"] "&INDEX(고압진공_재고현황!$D:$D,MATCH($D10,고압진공_재고현황!$E:$E,0)),IFERROR("[조립] "&INDEX(조립자재_재고현황!$D:$D,MATCH($D10,조립자재_재고현황!$E:$E,0)),"")) | H10: =IF(G10="","",COUNTIF($G$2:G10,"?*"))
A11: 창고 | B11: 전극 | C11: DXDR-100 | D11: 전극(100kV) (순철 도금) [DXDR-100] | G11: =IFERROR("["&INDEX(고압진공_재고현황!$A:$A,MATCH($D11,고압진공_재고현황!$E:$E,0))&"] "&INDEX(고압진공_재고현황!$D:$D,MATCH($D11,고압진공_재고현황!$E:$E,0)),IFERROR("[조립] "&INDEX(조립자재_재고현황!$D:$D,MATCH($D11,조립자재_재고현황!$E:$E,0)),"")) | H11: =IF(G11="","",COUNTIF($G$2:G11,"?*"))
A12: 창고 | B12: 필라멘트 | C12: DXDR-100 | D12: 텅스텐 필라멘트 [DXDR-100] | G12: =IFERROR("["&INDEX(고압진공_재고현황!$A:$A,MATCH($D12,고압진공_재고현황!$E:$E,0))&"] "&INDEX(고압진공_재고현황!$D:$D,MATCH($D12,고압진공_재고현황!$E:$E,0)),IFERROR("[조립] "&INDEX(조립자재_재고현황!$D:$D,MATCH($D12,조립자재_재고현황!$E:$E,0)),"")) | H12: =IF(G12="","",COUNTIF($G$2:G12,"?*"))
A13: 창고 | B13: 코바 | C13: DXDR-100 | D13: 에노드 [DXDR-100] | G13: =IFERROR("["&INDEX(고압진공_재고현황!$A:$A,MATCH($D13,고압진공_재고현황!$E:$E,0))&"] "&INDEX(고압진공_재고현황!$D:$D,MATCH($D13,고압진공_재고현황!$E:$E,0)),IFERROR("[조립] "&INDEX(조립자재_재고현황!$D:$D,MATCH($D13,조립자재_재고현황!$E:$E,0)),"")) | H13: =IF(G13="","",COUNTIF($G$2:G13,"?*"))
... A19: 창고 | B19: 필러 | C19: DXDR-100 | D19: 전극 필러 [DXDR-100] | G19: =IFERROR("["&INDEX(고압진공_재고현황!$A:$A,MATCH($D19,고압진공_재고현황!$E:$E,0))&"] "&INDEX(고압진공_재고현황!$D:$D,MATCH($D19,고압진공_재고현황!$E:$E,0)),IFERROR("[조립] "&INDEX(조립자재_재고현황!$D:$D,MATCH($D19,조립자재_재고현황!$E:$E,0)),"")) | H19: =IF(G19="","",COUNTIF($G$2:G19,"?*"))
A20: 창고 | B20: X-ray Tube | C20: DX3000, ADX4000W | D20: TUBE (60KV D-081B) [DX3000, ADX4000W] | E20: 신광포토레이 | G20: =IFERROR("["&INDEX(고압진공_재고현황!$A:$A,MATCH($D20,고압진공_재고현황!$E:$E,0))&"] "&INDEX(고압진공_재고현황!$D:$D,MATCH($D20,고압진공_재고현황!$E:$E,0)),IFERROR("[조립] "&INDEX(조립자재_재고현황!$D:$D,MATCH($D20,조립자재_재고현황!$E:$E,0)),"")) | H20: =IF(G20="","",COUNTIF($G$2:G20,"?*"))
A21: 창고 | B21: X-ray Tube | C21: COCOON | D21: TUBE (70KV D-041) [COCOON] | E21: 신광포토레이 | G21: =IFERROR("["&INDEX(고압진공_재고현황!$A:$A,MATCH($D21,고압진공_재고현황!$E:$E,0))&"] "&INDEX(고압진공_재고현황!$D:$D,MATCH($D21,고압진공_재고현황!$E:$E,0)),IFERROR("[조립] "&INDEX(조립자재_재고현황!$D:$D,MATCH($D21,조립자재_재고현황!$E:$E,0)),"")) | H21: =IF(G21="","",COUNTIF($G$2:G21,"?*"))
A22: 창고 | B22: X-ray Tube | C22: SOLO | D22: TUBE (70KV DXDR-070) [SOLO] | G22: =IFERROR("["&INDEX(고압진공_재고현황!$A:$A,MATCH($D22,고압진공_재고현황!$E:$E,0))&"] "&INDEX(고압진공_재고현황!$D:$D,MATCH($D22,고압진공_재고현황!$E:$E,0)),IFERROR("[조립] "&INDEX(조립자재_재고현황!$D:$D,MATCH($D22,조립자재_재고현황!$E:$E,0)),"")) | H22: =IF(G22="","",COUNTIF($G$2:G22,"?*"))
A23: 창고 | B23: X-ray Tube | C23: ADX6000 | D23: TUBE (80KV D-0813) [ADX6000] | E23: 신광포토레이 | G23: =IFERROR("["&INDEX(고압진공_재고현황!$A:$A,MATCH($D23,고압진공_재고현황!$E:$E,0))&"] "&INDEX(고압진공_재고현황!$D:$D,MATCH($D23,고압진공_재고현황!$E:$E,0)),IFERROR("[조립] "&INDEX(조립자재_재고현황!$D:$D,MATCH($D23,조립자재_재고현황!$E:$E,0)),"")) | H23: =IF(G23="","",COUNTIF($G$2:G23,"?*"))
A24: 창고 | B24: X-ray Tube | C24: ADX6000 | D24: TUBE (90kV OX / 70-1.0) [ADX6000] | E24: CEI | G24: =IFERROR("["&INDEX(고압진공_재고현황!$A:$A,MATCH($D24,고압진공_재고현황!$E:$E,0))&"] "&INDEX(고압진공_재고현황!$D:$D,MATCH($D24,고압진공_재고현황!$E:$E,0)),IFERROR("[조립] "&INDEX(조립자재_재고현황!$D:$D,MATCH($D24,조립자재_재고현황!$E:$E,0)),"")) | H24: =IF(G24="","",COUNTIF($G$2:G24,"?*"))
A25: 창고 | B25: X-ray Tube | C25: 100kV | D25: TUBE (100Kv DXDR-100) [100kV] | G25: =IFERROR("["&INDEX(고압진공_재고현황!$A:$A,MATCH($D25,고압진공_재고현황!$E:$E,0))&"] "&INDEX(고압진공_재고현황!$D:$D,MATCH($D25,고압진공_재고현황!$E:$E,0)),IFERROR("[조립] "&INDEX(조립자재_재고현황!$D:$D,MATCH($D25,조립자재_재고현황!$E:$E,0)),"")) | H25: =IF(G25="","",COUNTIF($G$2:G25,"?*"))
A26: 창고 | B26: 베이클라이트 | C26: DX3000, ADX4000W ADX6000 | D26: 튜브 하우징 파이프 (베이클라이트) [DX3000, ADX4000W ADX6000] | E26: 용봉화학 | G26: =IFERROR("["&INDEX(고압진공_재고현황!$A:$A,MATCH($D26,고압진공_재고현황!$E:$E,0))&"] "&INDEX(고압진공_재고현황!$D:$D,MATCH($D26,고압진공_재고현황!$E:$E,0)),IFERROR("[조립] "&INDEX(조립자재_재고현황!$D:$D,MATCH($D26,조립자재_재고현황!$E:$E,0)),"")) | H26: =IF(G26="","",COUNTIF($G$2:G26,"?*"))
A27: 창고 | B27: HDPE | C27: COCOON | D27: 튜브 하우징 파이프 (HDPE) [COCOON] | E27: 용봉화학 | G27: =IFERROR("["&INDEX(고압진공_재고현황!$A:$A,MATCH($D27,고압진공_재고현황!$E:$E,0))&"] "&INDEX(고압진공_재고현황!$D:$D,MATCH($D27,고압진공_재고현황!$E:$E,0)),IFERROR("[조립] "&INDEX(조립자재_재고현황!$D:$D,MATCH($D27,조립자재_재고현황!$E:$E,0)),"")) | H27: =IF(G27="","",COUNTIF($G$2:G27,"?*"))
A28: 창고 | B28: HDPE | C28: SOLO | D28: 튜브 하우징 파이프 (HDPE) [SOLO] | E28: 용봉화학 | G28: =IFERROR("["&INDEX(고압진공_재고현황!$A:$A,MATCH($D28,고압진공_재고현황!$E:$E,0))&"] "&INDEX(고압진공_재고현황!$D:$D,MATCH($D28,고압진공_재고현황!$E:$E,0)),IFERROR("[조립] "&INDEX(조립자재_재고현황!$D:$D,MATCH($D28,조립자재_재고현황!$E:$E,0)),"")) | H28: =IF(G28="","",COUNTIF($G$2:G28,"?*"))
A29: 창고 | B29: 램프 | C29: DX3000, ADX4000W COCOON | D29: 네온램프 (NEON-5T.5*13 red) [DX3000, ADX4000W COCOON] | E29: HLP | G29: =IFERROR("["&INDEX(고압진공_재고현황!$A:$A,MATCH($D29,고압진공_재고현황!$E:$E,0))&"] "&INDEX(고압진공_재고현황!$D:$D,MATCH($D29,고압진공_재고현황!$E:$E,0)),IFERROR("[조립] "&INDEX(조립자재_재고현황!$D:$D,MATCH($D29,조립자재_재고현황!$E:$E,0)),"")) | H29: =IF(G29="","",COUNTIF($G$2:G29,"?*"))
A30: 창고 | B30: 다이오드 | C30: DX3000, ADX4000W | D30: 고압 다이오드 (2CL77 (20KV, 5mA)) [DX3000, ADX4000W] | E30: 비지티 | G30: =IFERROR("["&INDEX(고압진공_재고현황!$A:$A,MATCH($D30,고압진공_재고현황!$E:$E,0))&"] "&INDEX(고압진공_재고현황!$D:$D,MATCH($D30,고압진공_재고현황!$E:$E,0)),IFERROR("[조립] "&INDEX(조립자재_재고현황!$D:$D,MATCH($D30,조립자재_재고현황!$E:$E,0)),"")) | H30: =IF(G30="","",COUNTIF($G$2:G30,"?*"))
A31: 창고 | B31: 다이오드 | C31: DX3000, ADX4000W ADX6000 | D31: 고압 다이오드 (DL1500) [DX3000, ADX4000W ADX6000] | E31: 비지티 | G31: =IFERROR("["&INDEX(고압진공_재고현황!$A:$A,MATCH($D31,고압진공_재고현황!$E:$E,0))&"] "&INDEX(고압진공_재고현황!$D:$D,MATCH($D31,고압진공_재고현황!$E:$E,0)),IFERROR("[조립] "&INDEX(조립자재_재고현황!$D:$D,MATCH($D31,조립자재_재고현황!$E:$E,0)),"")) | H31: =IF(G31="","",COUNTIF($G$2:G31,"?*"))
A32: 창고 | B32: 다이오드 | C32: COCOON | D32: 고압 다이오드 (DD1800) [COCOON] | E32: 비지티 | G32: =IFERROR("["&INDEX(고압진공_재고현황!$A:$A,MATCH($D32,고압진공_재고현황!$E:$E,0))&"] "&INDEX(고압진공_재고현황!$D:$D,MATCH($D32,고압진공_재고현황!$E:$E,0)),IFERROR("[조립] "&INDEX(조립자재_재고현황!$D:$D,MATCH($D32,조립자재_재고현황!$E:$E,0)),"")) | H32: =IF(G32="","",COUNTIF($G$2:G32,"?*"))
A33: 창고 | B33: 저항 | C33: DX3000, ADX4000W | D33: 15㏀ 고압용 저항 (15㏀±1％, DIP-1/4W) [DX3000, ADX4000W] | E33: HLP | G33: =IFERROR("["&INDEX(고압진공_재고현황!$A:$A,MATCH($D33,고압진공_재고현황!$E:$E,0))&"] "&INDEX(고압진공_재고현황!$D:$D,MATCH($D33,고압진공_재고현황!$E:$E,0)),IFERROR("[조립] "&INDEX(조립자재_재고현황!$D:$D,MATCH($D33,조립자재_재고현황!$E:$E,0)),"")) | H33: =IF(G33="","",COUNTIF($G$2:G33,"?*"))
A34: 창고 | B34: 저항 | C34: DX3000, ADX4000W ADX6000 | D34: 30㏀ 고압용 저항 (30㏀±1％, DIP-1/4W) [DX3000, ADX4000W ADX6000] | E34: HLP | G34: =IFERROR("["&INDEX(고압진공_재고현황!$A:$A,MATCH($D34,고압진공_재고현황!$E:$E,0))&"] "&INDEX(고압진공_재고현황!$D:$D,MATCH($D34,고압진공_재고현황!$E:$E,0)),IFERROR("[조립] "&INDEX(조립자재_재고현황!$D:$D,MATCH($D34,조립자재_재고현황!$E:$E,0)),"")) | H34: =IF(G34="","",COUNTIF($G$2:G34,"?*"))
A35: 창고 | B35: 저항 | C35: ADX6000 | D35: 500Ω 고압용 저항 (500Ω±1％, DIP-1/4W) [ADX6000] | E35: HLP | G35: =IFERROR("["&INDEX(고압진공_재고현황!$A:$A,MATCH($D35,고압진공_재고현황!$E:$E,0))&"] "&INDEX(고압진공_재고현황!$D:$D,MATCH($D35,고압진공_재고현황!$E:$E,0)),IFERROR("[조립] "&INDEX(조립자재_재고현황!$D:$D,MATCH($D35,조립자재_재고현황!$E:$E,0)),"")) | H35: =IF(G35="","",COUNTIF($G$2:G35,"?*"))
A36: 창고 | B36: 저항 | C36: DX3000, ADX4000W | D36: 1.7W,10kV 시멘트저항 짧은 것 (RK92-11XD 307J (1.7W,10kV,±5%,300ppm,Flat)) [DX3000, ADX4000W] | E36: 비지티 | G36: =IFERROR("["&INDEX(고압진공_재고현황!$A:$A,MATCH($D36,고압진공_재고현황!$E:$E,0))&"] "&INDEX(고압진공_재고현황!$D:$D,MATCH($D36,고압진공_재고현황!$E:$E,0)),IFERROR("[조립] "&INDEX(조립자재_재고현황!$D:$D,MATCH($D36,조립자재_재고현황!$E:$E,0)),"")) | H36: =IF(G36="","",COUNTIF($G$2:G36,"?*"))
A37: 창고 | B37: 저항 | C37: COCOON | D37: 2.7W,15kV 시멘트저항 긴 것 (RK92-18XD 307J (2.7W,15kV,±5%,300ppm,Flat)) [COCOON] | E37: 비지티 | G37: =IFERROR("["&INDEX(고압진공_재고현황!$A:$A,MATCH($D37,고압진공_재고현황!$E:$E,0))&"] "&INDEX(고압진공_재고현황!$D:$D,MATCH($D37,고압진공_재고현황!$E:$E,0)),IFERROR("[조립] "&INDEX(조립자재_재고현황!$D:$D,MATCH($D37,조립자재_재고현황!$E:$E,0)),"")) | H37: =IF(G37="","",COUNTIF($G$2:G37,"?*"))
... A84: 창고 | B84: AL | C84: ADX6000 | D84: 알루미늄 필터 (2T * Φ24) [ADX6000] | E84: 광전레이저 | G84: =IFERROR("["&INDEX(고압진공_재고현황!$A:$A,MATCH($D84,고압진공_재고현황!$E:$E,0))&"] "&INDEX(고압진공_재고현황!$D:$D,MATCH($D84,고압진공_재고현황!$E:$E,0)),IFERROR("[조립] "&INDEX(조립자재_재고현황!$D:$D,MATCH($D84,조립자재_재고현황!$E:$E,0)),"")) | H84: =IF(G84="","",COUNTIF($G$2:G84,"?*"))
A85: 창고 | B85: 오링 | C85: 공용 | D85: 방사구 오링 (2*18) [공용] | G85: =IFERROR("["&INDEX(고압진공_재고현황!$A:$A,MATCH($D85,고압진공_재고현황!$E:$E,0))&"] "&INDEX(고압진공_재고현황!$D:$D,MATCH($D85,고압진공_재고현황!$E:$E,0)),IFERROR("[조립] "&INDEX(조립자재_재고현황!$D:$D,MATCH($D85,조립자재_재고현황!$E:$E,0)),"")) | H85: =IF(G85="","",COUNTIF($G$2:G85,"?*"))
A86: 창고 | B86: BOARD | C86: DX3000, ADX4000W | D86: 3 PIN 커넥터 [DX3000, ADX4000W] | G86: =IFERROR("["&INDEX(고압진공_재고현황!$A:$A,MATCH($D86,고압진공_재고현황!$E:$E,0))&"] "&INDEX(고압진공_재고현황!$D:$D,MATCH($D86,고압진공_재고현황!$E:$E,0)),IFERROR("[조립] "&INDEX(조립자재_재고현황!$D:$D,MATCH($D86,조립자재_재고현황!$E:$E,0)),"")) | H86: =IF(G86="","",COUNTIF($G$2:G86,"?*"))
A87: 창고 | B87: BOARD | C87: DX3000,ADX4000W COCOON,ADX6000 | D87: 4 PIN 커넥터 [DX3000,ADX4000W COCOON,ADX6000] | G87: =IFERROR("["&INDEX(고압진공_재고현황!$A:$A,MATCH($D87,고압진공_재고현황!$E:$E,0))&"] "&INDEX(고압진공_재고현황!$D:$D,MATCH($D87,고압진공_재고현황!$E:$E,0)),IFERROR("[조립] "&INDEX(조립자재_재고현황!$D:$D,MATCH($D87,조립자재_재고현황!$E:$E,0)),"")) | H87: =IF(G87="","",COUNTIF($G$2:G87,"?*"))
A88: 창고 | B88: BOARD | C88: DX3000, ADX4000W | D88: 7핀 B/D [DX3000, ADX4000W] | E88: 한샘디지텍 | G88: =IFERROR("["&INDEX(고압진공_재고현황!$A:$A,MATCH($D88,고압진공_재고현황!$E:$E,0))&"] "&INDEX(고압진공_재고현황!$D:$D,MATCH($D88,고압진공_재고현황!$E:$E,0)),IFERROR("[조립] "&INDEX(조립자재_재고현황!$D:$D,MATCH($D88,조립자재_재고현황!$E:$E,0)),"")) | H88: =IF(G88="","",COUNTIF($G$2:G88,"?*"))
A89: 창고 | B89: BOARD | C89: DX3000 | D89: 9핀 B/D - TFT [DX3000] | E89: HLP | G89: =IFERROR("["&INDEX(고압진공_재고현황!$A:$A,MATCH($D89,고압진공_재고현황!$E:$E,0))&"] "&INDEX(고압진공_재고현황!$D:$D,MATCH($D89,고압진공_재고현황!$E:$E,0)),IFERROR("[조립] "&INDEX(조립자재_재고현황!$D:$D,MATCH($D89,조립자재_재고현황!$E:$E,0)),"")) | H89: =IF(G89="","",COUNTIF($G$2:G89,"?*"))
A90: 창고 | B90: BOARD | C90: COCOON | D90: 8핀 B/D [COCOON] | E90: 한샘디지텍 | G90: =IFERROR("["&INDEX(고압진공_재고현황!$A:$A,MATCH($D90,고압진공_재고현황!$E:$E,0))&"] "&INDEX(고압진공_재고현황!$D:$D,MATCH($D90,고압진공_재고현황!$E:$E,0)),IFERROR("[조립] "&INDEX(조립자재_재고현황!$D:$D,MATCH($D90,조립자재_재고현황!$E:$E,0)),"")) | H90: =IF(G90="","",COUNTIF($G$2:G90,"?*"))
A91: 창고 | B91: BOARD | C91: SOLO | D91: 9핀 B/D [SOLO] | E91: 한샘디지텍 | G91: =IFERROR("["&INDEX(고압진공_재고현황!$A:$A,MATCH($D91,고압진공_재고현황!$E:$E,0))&"] "&INDEX(고압진공_재고현황!$D:$D,MATCH($D91,고압진공_재고현황!$E:$E,0)),IFERROR("[조립] "&INDEX(조립자재_재고현황!$D:$D,MATCH($D91,조립자재_재고현황!$E:$E,0)),"")) | H91: =IF(G91="","",COUNTIF($G$2:G91,"?*"))
...

Sheet 매칭결과_통합
A1: 생산부 분류 | B1: 생산부 모델 | D1: 창고 분류 | E1: 창고 모델 | G1: 공급처 | I1: 생산부 품명 | J1: 창고 품명 | L1: 확정 분류 | M1: 확정 모델 | N1: 확정 품명 | P1: #
A2: =IF($J2="","",IFERROR(INDEX(고압진공_재고현황!$B:$B,MATCH($J2,고압진공_재고현황!$E:$E,0)),IFERROR(INDEX(조립자재_재고현황!$B:$B,MATCH($J2,조립자재_재고현황!$E:$E,0)),""))) | B2: =IF($J2="","",IFERROR(INDEX(고압진공_재고현황!$C:$C,MATCH($J2,고압진공_재고현황!$E:$E,0)),IFERROR(INDEX(조립자재_재고현황!$C:$C,MATCH($J2,조립자재_재고현황!$E:$E,0)),""))) | D2: =IF($P2="","",INDEX(창고_재고현황!$B:$B,$P2)) | E2: =IF($P2="","",INDEX(창고_재고현황!$C:$C,$P2)) | G2: =IF($P2="","",IF(INDEX(창고_재고현황!$E:$E,$P2)=0,"",INDEX(창고_재고현황!$E:$E,$P2))) | I2: =IF($J2="","",IFERROR(INDEX(고압진공_재고현황!$D:$D,MATCH($J2,고압진공_재고현황!$E:$E,0)),IFERROR(INDEX(조립자재_재고현황!$D:$D,MATCH($J2,조립자재_재고현황!$E:$E,0)),""))) | J2: =IF($P2="","",INDEX(창고_재고현황!$D:$D,$P2)) | P2: =IFERROR(MATCH(ROWS($P$2:P2),창고_재고현황!$H:$H,0),"")
A3: =IF($J3="","",IFERROR(INDEX(고압진공_재고현황!$B:$B,MATCH($J3,고압진공_재고현황!$E:$E,0)),IFERROR(INDEX(조립자재_재고현황!$B:$B,MATCH($J3,조립자재_재고현황!$E:$E,0)),""))) | B3: =IF($J3="","",IFERROR(INDEX(고압진공_재고현황!$C:$C,MATCH($J3,고압진공_재고현황!$E:$E,0)),IFERROR(INDEX(조립자재_재고현황!$C:$C,MATCH($J3,조립자재_재고현황!$E:$E,0)),""))) | D3: =IF($P3="","",INDEX(창고_재고현황!$B:$B,$P3)) | E3: =IF($P3="","",INDEX(창고_재고현황!$C:$C,$P3)) | G3: =IF($P3="","",IF(INDEX(창고_재고현황!$E:$E,$P3)=0,"",INDEX(창고_재고현황!$E:$E,$P3))) | I3: =IF($J3="","",IFERROR(INDEX(고압진공_재고현황!$D:$D,MATCH($J3,고압진공_재고현황!$E:$E,0)),IFERROR(INDEX(조립자재_재고현황!$D:$D,MATCH($J3,조립자재_재고현황!$E:$E,0)),""))) | J3: =IF($P3="","",INDEX(창고_재고현황!$D:$D,$P3)) | P3: =IFERROR(MATCH(ROWS($P$2:P3),창고_재고현황!$H:$H,0),"")
A4: =IF($J4="","",IFERROR(INDEX(고압진공_재고현황!$B:$B,MATCH($J4,고압진공_재고현황!$E:$E,0)),IFERROR(INDEX(조립자재_재고현황!$B:$B,MATCH($J4,조립자재_재고현황!$E:$E,0)),""))) | B4: =IF($J4="","",IFERROR(INDEX(고압진공_재고현황!$C:$C,MATCH($J4,고압진공_재고현황!$E:$E,0)),IFERROR(INDEX(조립자재_재고현황!$C:$C,MATCH($J4,조립자재_재고현황!$E:$E,0)),""))) | D4: =IF($P4="","",INDEX(창고_재고현황!$B:$B,$P4)) | E4: =IF($P4="","",INDEX(창고_재고현황!$C:$C,$P4)) | G4: =IF($P4="","",IF(INDEX(창고_재고현황!$E:$E,$P4)=0,"",INDEX(창고_재고현황!$E:$E,$P4))) | I4: =IF($J4="","",IFERROR(INDEX(고압진공_재고현황!$D:$D,MATCH($J4,고압진공_재고현황!$E:$E,0)),IFERROR(INDEX(조립자재_재고현황!$D:$D,MATCH($J4,조립자재_재고현황!$E:$E,0)),""))) | J4: =IF($P4="","",INDEX(창고_재고현황!$D:$D,$P4)) | P4: =IFERROR(MATCH(ROWS($P$2:P4),창고_재고현황!$H:$H,0),"")
A5: =IF($J5="","",IFERROR(INDEX(고압진공_재고현황!$B:$B,MATCH($J5,고압진공_재고현황!$E:$E,0)),IFERROR(INDEX(조립자재_재고현황!$B:$B,MATCH($J5,조립자재_재고현황!$E:$E,0)),""))) | B5: =IF($J5="","",IFERROR(INDEX(고압진공_재고현황!$C:$C,MATCH($J5,고압진공_재고현황!$E:$E,0)),IFERROR(INDEX(조립자재_재고현황!$C:$C,MATCH($J5,조립자재_재고현황!$E:$E,0)),""))) | D5: =IF($P5="","",INDEX(창고_재고현황!$B:$B,$P5)) | E5: =IF($P5="","",INDEX(창고_재고현황!$C:$C,$P5)) | G5: =IF($P5="","",IF(INDEX(창고_재고현황!$E:$E,$P5)=0,"",INDEX(창고_재고현황!$E:$E,$P5))) | I5: =IF($J5="","",IFERROR(INDEX(고압진공_재고현황!$D:$D,MATCH($J5,고압진공_재고현황!$E:$E,0)),IFERROR(INDEX(조립자재_재고현황!$D:$D,MATCH($J5,조립자재_재고현황!$E:$E,0)),""))) | J5: =IF($P5="","",INDEX(창고_재고현황!$D:$D,$P5)) | P5: =IFERROR(MATCH(ROWS($P$2:P5),창고_재고현황!$H:$H,0),"")
A6: =IF($J6="","",IFERROR(INDEX(고압진공_재고현황!$B:$B,MATCH($J6,고압진공_재고현황!$E:$E,0)),IFERROR(INDEX(조립자재_재고현황!$B:$B,MATCH($J6,조립자재_재고현황!$E:$E,0)),""))) | B6: =IF($J6="","",IFERROR(INDEX(고압진공_재고현황!$C:$C,MATCH($J6,고압진공_재고현황!$E:$E,0)),IFERROR(INDEX(조립자재_재고현황!$C:$C,MATCH($J6,조립자재_재고현황!$E:$E,0)),""))) | D6: =IF($P6="","",INDEX(창고_재고현황!$B:$B,$P6)) | E6: =IF($P6="","",INDEX(창고_재고현황!$C:$C,$P6)) | G6: =IF($P6="","",IF(INDEX(창고_재고현황!$E:$E,$P6)=0,"",INDEX(창고_재고현황!$E:$E,$P6))) | I6: =IF($J6="","",IFERROR(INDEX(고압진공_재고현황!$D:$D,MATCH($J6,고압진공_재고현황!$E:$E,0)),IFERROR(INDEX(조립자재_재고현황!$D:$D,MATCH($J6,조립자재_재고현황!$E:$E,0)),""))) | J6: =IF($P6="","",INDEX(창고_재고현황!$D:$D,$P6)) | P6: =IFERROR(MATCH(ROWS($P$2:P6),창고_재고현황!$H:$H,0),"")
A7: =IF($J7="","",IFERROR(INDEX(고압진공_재고현황!$B:$B,MATCH($J7,고압진공_재고현황!$E:$E,0)),IFERROR(INDEX(조립자재_재고현황!$B:$B,MATCH($J7,조립자재_재고현황!$E:$E,0)),""))) | B7: =IF($J7="","",IFERROR(INDEX(고압진공_재고현황!$C:$C,MATCH($J7,고압진공_재고현황!$E:$E,0)),IFERROR(INDEX(조립자재_재고현황!$C:$C,MATCH($J7,조립자재_재고현황!$E:$E,0)),""))) | D7: =IF($P7="","",INDEX(창고_재고현황!$B:$B,$P7)) | E7: =IF($P7="","",INDEX(창고_재고현황!$C:$C,$P7)) | G7: =IF($P7="","",IF(INDEX(창고_재고현황!$E:$E,$P7)=0,"",INDEX(창고_재고현황!$E:$E,$P7))) | I7: =IF($J7="","",IFERROR(INDEX(고압진공_재고현황!$D:$D,MATCH($J7,고압진공_재고현황!$E:$E,0)),IFERROR(INDEX(조립자재_재고현황!$D:$D,MATCH($J7,조립자재_재고현황!$E:$E,0)),""))) | J7: =IF($P7="","",INDEX(창고_재고현황!$D:$D,$P7)) | P7: =IFERROR(MATCH(ROWS($P$2:P7),창고_재고현황!$H:$H,0),"")
A8: =IF($J8="","",IFERROR(INDEX(고압진공_재고현황!$B:$B,MATCH($J8,고압진공_재고현황!$E:$E,0)),IFERROR(INDEX(조립자재_재고현황!$B:$B,MATCH($J8,조립자재_재고현황!$E:$E,0)),""))) | B8: =IF($J8="","",IFERROR(INDEX(고압진공_재고현황!$C:$C,MATCH($J8,고압진공_재고현황!$E:$E,0)),IFERROR(INDEX(조립자재_재고현황!$C:$C,MATCH($J8,조립자재_재고현황!$E:$E,0)),""))) | D8: =IF($P8="","",INDEX(창고_재고현황!$B:$B,$P8)) | E8: =IF($P8="","",INDEX(창고_재고현황!$C:$C,$P8)) | G8: =IF($P8="","",IF(INDEX(창고_재고현황!$E:$E,$P8)=0,"",INDEX(창고_재고현황!$E:$E,$P8))) | I8: =IF($J8="","",IFERROR(INDEX(고압진공_재고현황!$D:$D,MATCH($J8,고압진공_재고현황!$E:$E,0)),IFERROR(INDEX(조립자재_재고현황!$D:$D,MATCH($J8,조립자재_재고현황!$E:$E,0)),""))) | J8: =IF($P8="","",INDEX(창고_재고현황!$D:$D,$P8)) | P8: =IFERROR(MATCH(ROWS($P$2:P8),창고_재고현황!$H:$H,0),"")
A9: =IF($J9="","",IFERROR(INDEX(고압진공_재고현황!$B:$B,MATCH($J9,고압진공_재고현황!$E:$E,0)),IFERROR(INDEX(조립자재_재고현황!$B:$B,MATCH($J9,조립자재_재고현황!$E:$E,0)),""))) | B9: =IF($J9="","",IFERROR(INDEX(고압진공_재고현황!$C:$C,MATCH($J9,고압진공_재고현황!$E:$E,0)),IFERROR(INDEX(조립자재_재고현황!$C:$C,MATCH($J9,조립자재_재고현황!$E:$E,0)),""))) | D9: =IF($P9="","",INDEX(창고_재고현황!$B:$B,$P9)) | E9: =IF($P9="","",INDEX(창고_재고현황!$C:$C,$P9)) | G9: =IF($P9="","",IF(INDEX(창고_재고현황!$E:$E,$P9)=0,"",INDEX(창고_재고현황!$E:$E,$P9))) | I9: =IF($J9="","",IFERROR(INDEX(고압진공_재고현황!$D:$D,MATCH($J9,고압진공_재고현황!$E:$E,0)),IFERROR(INDEX(조립자재_재고현황!$D:$D,MATCH($J9,조립자재_재고현황!$E:$E,0)),""))) | J9: =IF($P9="","",INDEX(창고_재고현황!$D:$D,$P9)) | P9: =IFERROR(MATCH(ROWS($P$2:P9),창고_재고현황!$H:$H,0),"")
A10: =IF($J10="","",IFERROR(INDEX(고압진공_재고현황!$B:$B,MATCH($J10,고압진공_재고현황!$E:$E,0)),IFERROR(INDEX(조립자재_재고현황!$B:$B,MATCH($J10,조립자재_재고현황!$E:$E,0)),""))) | B10: =IF($J10="","",IFERROR(INDEX(고압진공_재고현황!$C:$C,MATCH($J10,고압진공_재고현황!$E:$E,0)),IFERROR(INDEX(조립자재_재고현황!$C:$C,MATCH($J10,조립자재_재고현황!$E:$E,0)),""))) | D10: =IF($P10="","",INDEX(창고_재고현황!$B:$B,$P10)) | E10: =IF($P10="","",INDEX(창고_재고현황!$C:$C,$P10)) | G10: =IF($P10="","",IF(INDEX(창고_재고현황!$E:$E,$P10)=0,"",INDEX(창고_재고현황!$E:$E,$P10))) | I10: =IF($J10="","",IFERROR(INDEX(고압진공_재고현황!$D:$D,MATCH($J10,고압진공_재고현황!$E:$E,0)),IFERROR(INDEX(조립자재_재고현황!$D:$D,MATCH($J10,조립자재_재고현황!$E:$E,0)),""))) | J10: =IF($P10="","",INDEX(창고_재고현황!$D:$D,$P10)) | P10: =IFERROR(MATCH(ROWS($P$2:P10),창고_재고현황!$H:$H,0),"")
A11: =IF($J11="","",IFERROR(INDEX(고압진공_재고현황!$B:$B,MATCH($J11,고압진공_재고현황!$E:$E,0)),IFERROR(INDEX(조립자재_재고현황!$B:$B,MATCH($J11,조립자재_재고현황!$E:$E,0)),""))) | B11: =IF($J11="","",IFERROR(INDEX(고압진공_재고현황!$C:$C,MATCH($J11,고압진공_재고현황!$E:$E,0)),IFERROR(INDEX(조립자재_재고현황!$C:$C,MATCH($J11,조립자재_재고현황!$E:$E,0)),""))) | D11: =IF($P11="","",INDEX(창고_재고현황!$B:$B,$P11)) | E11: =IF($P11="","",INDEX(창고_재고현황!$C:$C,$P11)) | G11: =IF($P11="","",IF(INDEX(창고_재고현황!$E:$E,$P11)=0,"",INDEX(창고_재고현황!$E:$E,$P11))) | I11: =IF($J11="","",IFERROR(INDEX(고압진공_재고현황!$D:$D,MATCH($J11,고압진공_재고현황!$E:$E,0)),IFERROR(INDEX(조립자재_재고현황!$D:$D,MATCH($J11,조립자재_재고현황!$E:$E,0)),""))) | J11: =IF($P11="","",INDEX(창고_재고현황!$D:$D,$P11)) | P11: =IFERROR(MATCH(ROWS($P$2:P11),창고_재고현황!$H:$H,0),"")
A12: =IF($J12="","",IFERROR(INDEX(고압진공_재고현황!$B:$B,MATCH($J12,고압진공_재고현황!$E:$E,0)),IFERROR(INDEX(조립자재_재고현황!$B:$B,MATCH($J12,조립자재_재고현황!$E:$E,0)),""))) | B12: =IF($J12="","",IFERROR(INDEX(고압진공_재고현황!$C:$C,MATCH($J12,고압진공_재고현황!$E:$E,0)),IFERROR(INDEX(조립자재_재고현황!$C:$C,MATCH($J12,조립자재_재고현황!$E:$E,0)),""))) | D12: =IF($P12="","",INDEX(창고_재고현황!$B:$B,$P12)) | E12: =IF($P12="","",INDEX(창고_재고현황!$C:$C,$P12)) | G12: =IF($P12="","",IF(INDEX(창고_재고현황!$E:$E,$P12)=0,"",INDEX(창고_재고현황!$E:$E,$P12))) | I12: =IF($J12="","",IFERROR(INDEX(고압진공_재고현황!$D:$D,MATCH($J12,고압진공_재고현황!$E:$E,0)),IFERROR(INDEX(조립자재_재고현황!$D:$D,MATCH($J12,조립자재_재고현황!$E:$E,0)),""))) | J12: =IF($P12="","",INDEX(창고_재고현황!$D:$D,$P12)) | P12: =IFERROR(MATCH(ROWS($P$2:P12),창고_재고현황!$H:$H,0),"")
A13: =IF($J13="","",IFERROR(INDEX(고압진공_재고현황!$B:$B,MATCH($J13,고압진공_재고현황!$E:$E,0)),IFERROR(INDEX(조립자재_재고현황!$B:$B,MATCH($J13,조립자재_재고현황!$E:$E,0)),""))) | B13: =IF($J13="","",IFERROR(INDEX(고압진공_재고현황!$C:$C,MATCH($J13,고압진공_재고현황!$E:$E,0)),IFERROR(INDEX(조립자재_재고현황!$C:$C,MATCH($J13,조립자재_재고현황!$E:$E,0)),""))) | D13: =IF($P13="","",INDEX(창고_재고현황!$B:$B,$P13)) | E13: =IF($P13="","",INDEX(창고_재고현황!$C:$C,$P13)) | G13: =IF($P13="","",IF(INDEX(창고_재고현황!$E:$E,$P13)=0,"",INDEX(창고_재고현황!$E:$E,$P13))) | I13: =IF($J13="","",IFERROR(INDEX(고압진공_재고현황!$D:$D,MATCH($J13,고압진공_재고현황!$E:$E,0)),IFERROR(INDEX(조립자재_재고현황!$D:$D,MATCH($J13,조립자재_재고현황!$E:$E,0)),""))) | J13: =IF($P13="","",INDEX(창고_재고현황!$D:$D,$P13)) | P13: =IFERROR(MATCH(ROWS($P$2:P13),창고_재고현황!$H:$H,0),"")
... A301: =IF($J301="","",IFERROR(INDEX(고압진공_재고현황!$B:$B,MATCH($J301,고압진공_재고현황!$E:$E,0)),IFERROR(INDEX(조립자재_재고현황!$B:$B,MATCH($J301,조립자재_재고현황!$E:$E,0)),""))) | B301: =IF($J301="","",IFERROR(INDEX(고압진공_재고현황!$C:$C,MATCH($J301,고압진공_재고현황!$E:$E,0)),IFERROR(INDEX(조립자재_재고현황!$C:$C,MATCH($J301,조립자재_재고현황!$E:$E,0)),""))) | D301: =IF($P301="","",INDEX(창고_재고현황!$B:$B,$P301)) | E301: =IF($P301="","",INDEX(창고_재고현황!$C:$C,$P301)) | G301: =IF($P301="","",IF(INDEX(창고_재고현황!$E:$E,$P301)=0,"",INDEX(창고_재고현황!$E:$E,$P301))) | I301: =IF($J301="","",IFERROR(INDEX(고압진공_재고현황!$D:$D,MATCH($J301,고압진공_재고현황!$E:$E,0)),IFERROR(INDEX(조립자재_재고현황!$D:$D,MATCH($J301,조립자재_재고현황!$E:$E,0)),""))) | J301: =IF($P301="","",INDEX(창고_재고현황!$D:$D,$P301)) | P301: =IFERROR(MATCH(ROWS($P$2:P301),창고_재고현황!$H:$H,0),"")
